Workbook

Sheet 2018-2026
EI1: GUARDIA NACIONAL
EI2: UNIDAD DE ÓRGANOS ESPECIALIZADOS POR COMPETENCIA
EI3: DIRECCIÓN GENERAL CIENTÍFICA
A5: INFORME DE ACCIONES Y RESULTADOS EN EL MARCO DE LA ESTRATEGIA NACIONAL DE SEGURIDAD PÚBLICA (ENSP)
A8: VIII. SEGURIDAD PÚBLICA, SEGURIDAD NACIONAL Y PAZ
A10: CIBERSEGURIDAD
A12: Ciberseguridad | B12: Concepto | C12: 43435 | D12: 43466 | E12: 43497 | F12: 43525 | G12: 43556 | H12: 43586 | I12: 43617 | J12: 43647 | K12: 43678 | L12: 43709 | M12: 43739 | N12: 43770 | O12: 43800 | P12: 43831 | Q12: 43862 | R12: 43891 | S12: 43922 | T12: 43952 | U12: 43983 | V12: 44013 | W12: 44044 | X12: 44075 | Y12: 44105 | Z12: 44136 | AA12: 44166 | AB12: 44197 | AC12: 44228 | AD12: 44256 | AE12: 44287 | AF12: 44317 | AG12: 44348 | AH12: 44378 | AI12: 44409 | AJ12: 44440 | AK12: 44470 | AL12: 44501 | AM12: 44531 | AN12: 44562 | AO12: 44593 | AP12: 44621 | AQ12: 44652 | AR12: 44703 | AS12: 44734 | AT12: 44764 | AU12: 44774 | AV12: 44819 | AW12: 44864 | AX12: 44866 | AY12: 44896 | AZ12: 44927 | BA12: 44956 | BB12: 44972 | BC12: 44985 | BD12: 45000 | BE12: 45015 | BF12: 45031 | BG12: 45046 | BH12: 45061 | BI12: 45076 | BJ12: 45092 | BK12: 45107 | BL12: 45122 | BM12: 45137 | BN12: 45139 | BO12: 45168 | BP12: 45184 | BQ12: 45199 | BR12: 45214 | BS12: 45229 | BT12: 45245 | BU12: 45260 | BV12: 45275 | BW12: 45290 | BX12: 45306 | BY12: 45321 | BZ12: 45337 | CA12: 45351 | CB12: 45366 | CC12: 45381 | CD12: 45397 | CE12: 45412 | CF12: 45427 | CG12: 45442 | CH12: 45458 | CI12: 45473 | CJ12: 45488 | CK12: 45503 | CL12: 45519 | CM12: 45534 | CN12: 45550 | CO12: 45565 | CP12: 45580 | CQ12: 45595 | CR12: 45611 | CS12: 45626 | CT12: 45641 | CU12: 45656 | CV12: 45658 | CW12: 45658 | CX12: 45689 | CY12: 45689 | CZ12: 45717 | DA12: 45717 | DB12: 38443 | DC12: 45748 | DD12: 45778 | DE12: 45778 | DF12: 45809 | DG12: 45809 | DH12: 45839 | DI12: 45839 | DJ12: 45870 | DK12: 45870 | DL12: 45901 | DM12: 45901 | DN12: 45931 | DO12: 45931 | DP12: 45962 | DQ12: 45962 | DR12: 45992 | DS12: 45992 | DT12: 46023 | DU12: 46023 | DV12: 46068 | DW12: 46081 | DX12: 46096 | DY12: 46111 | DZ12: 46127 | EA12: 46142 | EB12: 46157 | EC12: 46172 | ED12: 46188 | EE12: 46203 | EF12: 46218 | EG12: 46233 | EH12: NUEVA ADMINISTRACION Oct 2024- A LA FECHA | EI12: ACUMULADO 01 DIC 2018- LA FECHA | EJ12: CREACION GN JULIO 2019 A LA FECHA | EK12: LABORES DEFENSA | EL12: 2018 | EM12: 2019 | EN12: 2020 | EO12: 2021 | EP12: 2022 | EQ12: 2023 | ER12: 2024 | ES12: 2025 | ET12: 2026 | EU12: SSPC | EV12: ENSP | EX12: PPT JACOBO 1° Dic. 2018 al 30 sep. de 2024 | EY12: marzo 2029 -agosto 2025
A13: Forense Digital | B13: Servicios | C13: 75 | D13: 38 | E13: 34 | F13: 32 | G13: 46 | H13: 39 | I13: 96 | J13: 4 | K13: 18 | L13: 140 | M13: 160 | N13: 6 | O13: 95 | P13: 65 | Q13: 0 | R13: 56 | S13: 54 | T13: 2 | U13: 0 | V13: 4 | W13: 4 | X13: 2 | Y13: 23 | Z13: 8 | AA13: 5 | AB13: 6 | AC13: 3 | AD13: 6 | AE13: 67 | AF13: 0 | AG13: 77 | AH13: 2 | AI13: 14 | AJ13: 13 | AK13: 4 | AL13: 3 | AM13: 0 | AN13: 0 | AO13: 3 | AP13: 0 | AQ13: 0 | AR13: 0 | AS13: 0 | AT13: 2 | AU13: 134 | AV13: 3 | AW13: 17 | AX13: 129 | AY13: 0 | AZ13: 0 | BA13: 0 | BB13: 7 | BC13: 0 | BD13: 1 | BE13: 0 | BF13: 141 | BG13: 6 | BH13: 1 | BI13: 1 | BJ13: 0 | BK13: 153 | BL13: 0 | BM13: 0 | BN13: 5 | BO13: 0 | BP13: 3 | BQ13: 0 | BR13: 2 | BS13: 0 | BT13: 6 | BU13: 6 | BV13: 3 | BW13: 26 | BX13: 1 | BY13: 3 | BZ13: 1 | CA13: 1 | CB13: 1 | CC13: 7 | CD13: 3 | CE13: 4 | CF13: 14 | CG13: 9 | CH13: 17 | CI13: 8 | CJ13: 16 | CK13: 8 | CL13: 4 | CM13: 7 | CN13: =11+6 -> 17 | CO13: 21 | CP13: 3 | CQ13: 22 | CR13: 9 | CS13: 4 | CT13: 4 | CU13: 2 | CV13: 1 | CW13: 8 | CX13: 0 | CY13: 7 | CZ13: 3 | DA13: 5 | DB13: 0 | DC13: 1 | DD13: 3 | DE13: 3 | DF13: 0 | DG13: 11 | DH13: 3 | DI13: 4 | DJ13: 15 | DK13: 0 | DL13: 7 | DM13: 7 | DN13: 0 | DO13: 0 | DP13: 1 | DQ13: 17 | DR13: 14 | DS13: 2 | EH13: =SUM(CP13:EG13) -> 156 | EI13: =SUM(C13:DM13) -> 2114 | EJ13: =SUM(J13:DM13) -> 1754 | EK13: =SUM(DL13:EG13) -> 48 | EL13: =SUM(C13:C13) -> 75 | EM13: =SUM(D13:O13) -> 708 | EN13: =SUM(P13:AA13) -> 223 | EO13: =SUM(AB13:AM13) -> 195 | EP13: =SUM(AN13:AY13) -> 288 | EQ13: =SUM(AZ13:BW13) -> 361 | ER13: =SUM(BX13:CU13) -> 186 | ES13: =SUM(CV13:DS13) -> 112 | ET13: =SUM(DT13:EG13) -> 0 | EU13: =SUM(CW13:EH13) -> 267 | EV13: =SUM(CX13:EI13) -> 2373 | EW13: =SUM(CY13:EJ13) -> 4127 | EX13: =SUM(CZ13:EL13) -> 4243 | EY13: =SUM(F13:DK13) -> 1953
A14: Forense Digital | B14: Solicitudes | C14: 6 | D14: 3 | E14: 11 | F14: 6 | G14: 4 | H14: 5 | I14: 9 | J14: 3 | K14: 7 | L14: 5 | M14: 6 | N14: 4 | O14: 6 | P14: 4 | Q14: 0 | R14: 4 | S14: 3 | T14: 2 | U14: 0 | V14: 1 | W14: 1 | X14: 3 | Y14: 3 | Z14: 1 | AA14: 2 | AB14: 3 | AC14: 1 | AD14: 2 | AE14: 3 | AF14: 0 | AG14: 2 | AH14: 1 | AI14: 5 | AJ14: 1 | AK14: 3 | AL14: 2 | AM14: 0 | AN14: 0 | AO14: 1 | AP14: 0 | AQ14: 0 | AR14: 0 | AS14: 0 | AT14: 1 | AU14: 3 | AV14: 1 | AW14: 1 | AX14: 3 | AY14: 0 | AZ14: 0 | BA14: 0 | BB14: 2 | BC14: 0 | BD14: 1 | BE14: 0 | BF14: 2 | BG14: 3 | BH14: 1 | BI14: 1 | BJ14: 0 | BK14: 4 | BL14: 0 | BM14: 0 | BN14: 1 | BO14: 0 | BP14: 1 | BQ14: 0 | BR14: 1 | BS14: 0 | BT14: 3 | BU14: 5 | BV14: 2 | BW14: 9 | BX14: 1 | BY14: 2 | BZ14: 1 | CA14: 1 | CB14: 1 | CC14: 2 | CD14: 1 | CE14: 2 | CF14: 4 | CG14: 3 | CH14: 4 | CI14: 2 | CJ14: 6 | CK14: 6 | CL14: 2 | CM14: 3 | CN14: =5+3 -> 8 | CO14: 3 | CP14: 1 | CQ14: 5 | CR14: 2 | CS14: 2 | CT14: 3 | CU14: 2 | CV14: 1 | CW14: 6 | CX14: 1 | CY14: 3 | CZ14: 4 | DA14: 2 | DB14: 0 | DC14: 1 | DD14: 1 | DE14: 3 | DF14: 0 | DG14: 3 | DH14: 5 | DI14: 3 | DJ14: 8 | DK14: 0 | DL14: 5 | DM14: 4 | EH14: =SUM(CP14:EG14) -> 65 | EI14: =SUM(C14:DM14) -> 285 | EJ14: =SUM(J14:DM14) -> 241 | EK14: =SUM(DL14:EG14) -> 9 | EL14: =SUM(C14:C14) -> 6 | EM14: =SUM(D14:O14) -> 69 | EN14: =SUM(P14:AA14) -> 24 | EO14: =SUM(AB14:AM14) -> 23 | EP14: =SUM(AN14:AY14) -> 10 | EQ14: =SUM(AZ14:BW14) -> 36 | ER14: =SUM(BX14:CU14) -> 67 | ES14: =SUM(CV14:DS14) -> 50 | ET14: =SUM(DT14:EG14) -> 0 | EU14: =SUM(BP14:CK14) -> 57 | EV14: =SUM(CD14:CU14) -> 59 | EX14: =SUM(C14:CO14) -> 220 | EY14: =SUM(F14:DK14) -> 256 | EZ14: jaz
A15: servicios especializados de ciberseguridad | EH15: =SUM(CP15:EG15) -> 0 | EK15: =SUM(DL15:EG15) -> 0 | ET15: =SUM(DT15:EG15) -> 0
A16: Gestiones de bajas de sitios: | C16: 0 | D16: 0 | E16: 0 | F16: 0 | G16: 0 | H16: 0 | I16: 0 | J16: 0 | K16: 0 | L16: 0 | M16: 0 | N16: 0 | O16: 0 | P16: 0 | Q16: 0 | R16: 0 | S16: 0 | T16: 0 | U16: 0 | V16: 0 | W16: 0 | X16: 0 | Y16: 0 | Z16: 0 | AA16: 0 | AB16: 0 | AC16: 0 | AD16: 0 | AE16: 0 | AF16: 0 | AG16: 0 | AH16: 0 | AI16: 0 | AJ16: 0 | AK16: 0 | AL16: 0 | AM16: 0 | AN16: 0 | AO16: 0 | AP16: 0 | AQ16: 0 | AR16: 0 | AS16: 0 | AT16: 0 | AU16: 0 | AV16: 0 | AW16: 0 | AX16: 0 | AY16: 0 | AZ16: 0 | BA16: 0 | BB16: 0 | BC16: 0 | BD16: 0 | BE16: 0 | BF16: 0 | BG16: 0 | BH16: 0 | BI16: 0 | BJ16: 0 | BK16: 0 | BL16: 0 | BM16: 0 | BN16: 0 | BO16: 0 | BP16: 0 | BQ16: 0 | BR16: 0 | BS16: 0 | BT16: 0 | BU16: 0 | BV16: 0 | BW16: 0 | BX16: 0 | BY16: 0 | BZ16: 0 | CA16: 0 | CB16: 0 | CC16: 0 | CD16: 0 | CE16: 0 | CF16: 0 | CG16: 0 | CH16: 0 | CI16: 0 | CJ16: 0 | CK16: 0 | CL16: 0 | CM16: 0 | CN16: 0 | CO16: 0 | CP16: 0 | CQ16: 0 | CR16: 0 | CS16: 0 | CT16: 0 | CU16: 0 | CV16: 0 | CW16: 0 | CX16: 0 | CY16: 0 | CZ16: 0 | DA16: 0 | DB16: 0 | DC16: 0 | DD16: 0 | DE16: 0 | DF16: 0 | DG16: 0 | DH16: 0 | DI16: 0 | DJ16: 0 | DK16: 0 | DL16: 0 | DM16: 0 | DN16: 0 | DO16: 0 | DP16: 0 | DQ16: 0 | DR16: 0 | DS16: 0 | DT16: 0 | DU16: 0 | DV16: 0 | DW16: 0 | DX16: 0 | DY16: 0 | DZ16: 22 | EA16: 0 | EB16: 0 | EC16: 0 | ED16: 0 | EE16: 0 | EF16: 0 | EG16: 0 | EH16: =SUM(CP16:EG16) -> 22 | EK16: =SUM(DL16:EG16) -> 22 | ET16: =SUM(DT16:EG16) -> 22
A17: Gestiones de suspensión de contenido | C17: 0 | D17: 0 | E17: 0 | F17: 0 | G17: 0 | H17: 0 | I17: 0 | J17: 0 | K17: 0 | L17: 0 | M17: 0 | N17: 0 | O17: 0 | P17: 0 | Q17: 0 | R17: 0 | S17: 0 | T17: 0 | U17: 0 | V17: 0 | W17: 0 | X17: 0 | Y17: 0 | Z17: 0 | AA17: 0 | AB17: 0 | AC17: 0 | AD17: 0 | AE17: 0 | AF17: 0 | AG17: 0 | AH17: 0 | AI17: 0 | AJ17: 0 | AK17: 0 | AL17: 0 | AM17: 0 | AN17: 0 | AO17: 0 | AP17: 0 | AQ17: 0 | AR17: 0 | AS17: 0 | AT17: 0 | AU17: 0 | AV17: 0 | AW17: 0 | AX17: 0 | AY17: 0 | AZ17: 0 | BA17: 0 | BB17: 0 | BC17: 0 | BD17: 0 | BE17: 0 | BF17: 0 | BG17: 0 | BH17: 0 | BI17: 0 | BJ17: 0 | BK17: 0 | BL17: 0 | BM17: 0 | BN17: 0 | BO17: 0 | BP17: 0 | BQ17: 0 | BR17: 0 | BS17: 0 | BT17: 0 | BU17: 0 | BV17: 0 | BW17: 0 | BX17: 0 | BY17: 0 | BZ17: 0 | CA17: 0 | CB17: 0 | CC17: 0 | CD17: 0 | CE17: 0 | CF17: 0 | CG17: 0 | CH17: 0 | CI17: 0 | CJ17: 0 | CK17: 0 | CL17: 0 | CM17: 0 | CN17: 0 | CO17: 0 | CP17: 0 | CQ17: 0 | CR17: 0 | CS17: 0 | CT17: 0 | CU17: 0 | CV17: 0 | CW17: 0 | CX17: 0 | CY17: 0 | CZ17: 0 | DA17: 0 | DB17: 0 | DC17: 0 | DD17: 0 | DE17: 0 | DF17: 0 | DG17: 0 | DH17: 0 | DI17: 0 | DJ17: 0 | DK17: 0 | DL17: 0 | DM17: 0 | DN17: 0 | DO17: 0 | DP17: 0 | DQ17: 0 | DR17: 0 | DS17: 0 | DT17: 0 | DU17: 0 | DV17: 0 | DW17: 0 | DX17: 0 | DY17: 0 | DZ17: 12 | EA17: 0 | EB17: 0 | EC17: 0 | ED17: 0 | EE17: 0 | EF17: 0 | EG17: 0 | EH17: =SUM(CP17:EG17) -> 12 | EK17: =SUM(DL17:EG17) -> 12 | ET17: =SUM(DT17:EG17) -> 12
A18: Análisis de vulnerabilidades | C18: 0 | D18: 0 | E18: 0 | F18: 0 | G18: 0 | H18: 0 | I18: 0 | J18: 0 | K18: 0 | L18: 0 | M18: 0 | N18: 0 | O18: 0 | P18: 0 | Q18: 0 | R18: 0 | S18: 0 | T18: 0 | U18: 0 | V18: 0 | W18: 0 | X18: 0 | Y18: 0 | Z18: 0 | AA18: 0 | AB18: 0 | AC18: 0 | AD18: 0 | AE18: 0 | AF18: 0 | AG18: 0 | AH18: 0 | AI18: 0 | AJ18: 0 | AK18: 0 | AL18: 0 | AM18: 0 | AN18: 0 | AO18: 0 | AP18: 0 | AQ18: 0 | AR18: 0 | AS18: 0 | AT18: 0 | AU18: 0 | AV18: 0 | AW18: 0 | AX18: 0 | AY18: 0 | AZ18: 0 | BA18: 0 | BB18: 0 | BC18: 0 | BD18: 0 | BE18: 0 | BF18: 0 | BG18: 0 | BH18: 0 | BI18: 0 | BJ18: 0 | BK18: 0 | BL18: 0 | BM18: 0 | BN18: 0 | BO18: 0 | BP18: 0 | BQ18: 0 | BR18: 0 | BS18: 0 | BT18: 0 | BU18: 0 | BV18: 0 | BW18: 0 | BX18: 0 | BY18: 0 | BZ18: 0 | CA18: 0 | CB18: 0 | CC18: 0 | CD18: 0 | CE18: 0 | CF18: 0 | CG18: 0 | CH18: 0 | CI18: 0 | CJ18: 0 | CK18: 0 | CL18: 0 | CM18: 0 | CN18: 0 | CO18: 0 | CP18: 0 | CQ18: 0 | CR18: 0 | CS18: 0 | CT18: 0 | CU18: 0 | CV18: 0 | CW18: 0 | CX18: 0 | CY18: 0 | CZ18: 0 | DA18: 0 | DB18: 0 | DC18: 0 | DD18: 0 | DE18: 0 | DF18: 0 | DG18: 0 | DH18: 0 | DI18: 0 | DJ18: 0 | DK18: 0 | DL18: 0 | DM18: 0 | DN18: 0 | DO18: 0 | DP18: 0 | DQ18: 0 | DR18: 0 | DS18: 0 | DT18: 0 | DU18: 0 | DV18: 0 | DW18: 0 | DX18: 0 | DY18: 0 | DZ18: 3 | EA18: 0 | EB18: 0 | EC18: 0 | ED18: 0 | EE18: 0 | EF18: 0 | EG18: 0 | EH18: =SUM(CP18:EG18) -> 3 | EK18: =SUM(DL18:EG18) -> 3 | ET18: =SUM(DT18:EG18) -> 3
A19: Colaboración Nacional | C19: 0 | D19: 0 | E19: 0 | F19: 0 | G19: 0 | H19: 0 | I19: 0 | J19: 0 | K19: 0 | L19: 0 | M19: 0 | N19: 0 | O19: 0 | P19: 0 | Q19: 0 | R19: 0 | S19: 0 | T19: 0 | U19: 0 | V19: 0 | W19: 0 | X19: 0 | Y19: 0 | Z19: 0 | AA19: 0 | AB19: 0 | AC19: 0 | AD19: 0 | AE19: 0 | AF19: 0 | AG19: 0 | AH19: 0 | AI19: 0 | AJ19: 0 | AK19: 0 | AL19: 0 | AM19: 0 | AN19: 0 | AO19: 0 | AP19: 0 | AQ19: 0 | AR19: 0 | AS19: 0 | AT19: 0 | AU19: 0 | AV19: 0 | AW19: 0 | AX19: 0 | AY19: 0 | AZ19: 0 | BA19: 0 | BB19: 0 | BC19: 0 | BD19: 0 | BE19: 0 | BF19: 0 | BG19: 0 | BH19: 0 | BI19: 0 | BJ19: 0 | BK19: 0 | BL19: 0 | BM19: 0 | BN19: 0 | BO19: 0 | BP19: 0 | BQ19: 0 | BR19: 0 | BS19: 0 | BT19: 0 | BU19: 0 | BV19: 0 | BW19: 0 | BX19: 0 | BY19: 0 | BZ19: 0 | CA19: 0 | CB19: 0 | CC19: 0 | CD19: 0 | CE19: 0 | CF19: 0 | CG19: 0 | CH19: 0 | CI19: 0 | CJ19: 0 | CK19: 0 | CL19: 0 | CM19: 0 | CN19: 0 | CO19: 0 | CP19: 0 | CQ19: 0 | CR19: 0 | CS19: 0 | CT19: 0 | CU19: 0 | CV19: 0 | CW19: 0 | CX19: 0 | CY19: 0 | CZ19: 0 | DA19: 0 | DB19: 0 | DC19: 0 | DD19: 0 | DE19: 0 | DF19: 0 | DG19: 0 | DH19: 0 | DI19: 0 | DJ19: 0 | DK19: 0 | DL19: 0 | DM19: 0 | DN19: 0 | DO19: 0 | DP19: 0 | DQ19: 0 | DR19: 0 | DS19: 0 | DT19: 0 | DU19: 0 | DV19: 0 | DW19: 0 | DX19: 0 | DY19: 0 | DZ19: 0 | EA19: 0 | EB19: 0 | EC19: 0 | ED19: 0 | EE19: 0 | EF19: 0 | EG19: 0 | EH19: =SUM(CP19:EG19) -> 0 | EK19: =SUM(DL19:EG19) -> 0 | ET19: =SUM(DT19:EG19) -> 0
A20: Asesorías técnico/legales | C20: 0 | D20: 0 | E20: 0 | F20: 0 | G20: 0 | H20: 0 | I20: 0 | J20: 0 | K20: 0 | L20: 0 | M20: 0 | N20: 0 | O20: 0 | P20: 0 | Q20: 0 | R20: 0 | S20: 0 | T20: 0 | U20: 0 | V20: 0 | W20: 0 | X20: 0 | Y20: 0 | Z20: 0 | AA20: 0 | AB20: 0 | AC20: 0 | AD20: 0 | AE20: 0 | AF20: 0 | AG20: 0 | AH20: 0 | AI20: 0 | AJ20: 0 | AK20: 0 | AL20: 0 | AM20: 0 | AN20: 0 | AO20: 0 | AP20: 0 | AQ20: 0 | AR20: 0 | AS20: 0 | AT20: 0 | AU20: 0 | AV20: 0 | AW20: 0 | AX20: 0 | AY20: 0 | AZ20: 0 | BA20: 0 | BB20: 0 | BC20: 0 | BD20: 0 | BE20: 0 | BF20: 0 | BG20: 0 | BH20: 0 | BI20: 0 | BJ20: 0 | BK20: 0 | BL20: 0 | BM20: 0 | BN20: 0 | BO20: 0 | BP20: 0 | BQ20: 0 | BR20: 0 | BS20: 0 | BT20: 0 | BU20: 0 | BV20: 0 | BW20: 0 | BX20: 0 | BY20: 0 | BZ20: 0 | CA20: 0 | CB20: 0 | CC20: 0 | CD20: 0 | CE20: 0 | CF20: 0 | CG20: 0 | CH20: 0 | CI20: 0 | CJ20: 0 | CK20: 0 | CL20: 0 | CM20: 0 | CN20: 0 | CO20: 0 | CP20: 0 | CQ20: 0 | CR20: 0 | CS20: 0 | CT20: 0 | CU20: 0 | CV20: 0 | CW20: 0 | CX20: 0 | CY20: 0 | CZ20: 0 | DA20: 0 | DB20: 0 | DC20: 0 | DD20: 0 | DE20: 0 | DF20: 0 | DG20: 0 | DH20: 0 | DI20: 0 | DJ20: 0 | DK20: 0 | DL20: 0 | DM20: 0 | DN20: 0 | DO20: 0 | DP20: 0 | DQ20: 0 | DR20: 0 | DS20: 0 | DT20: 0 | DU20: 0 | DV20: 0 | DW20: 0 | DX20: 0 | DY20: 0 | DZ20: 2 | EA20: 0 | EB20: 0 | EC20: 0 | ED20: 0 | EE20: 0 | EF20: 0 | EG20: 0 | EH20: =SUM(CP20:EG20) -> 2 | EK20: =SUM(DL20:EG20) -> 2 | ET20: =SUM(DT20:EG20) -> 2
A21: Análisis de forense digital | C21: 0 | D21: 0 | E21: 0 | F21: 0 | G21: 0 | H21: 0 | I21: 0 | J21: 0 | K21: 0 | L21: 0 | M21: 0 | N21: 0 | O21: 0 | P21: 0 | Q21: 0 | R21: 0 | S21: 0 | T21: 0 | U21: 0 | V21: 0 | W21: 0 | X21: 0 | Y21: 0 | Z21: 0 | AA21: 0 | AB21: 0 | AC21: 0 | AD21: 0 | AE21: 0 | AF21: 0 | AG21: 0 | AH21: 0 | AI21: 0 | AJ21: 0 | AK21: 0 | AL21: 0 | AM21: 0 | AN21: 0 | AO21: 0 | AP21: 0 | AQ21: 0 | AR21: 0 | AS21: 0 | AT21: 0 | AU21: 0 | AV21: 0 | AW21: 0 | AX21: 0 | AY21: 0 | AZ21: 0 | BA21: 0 | BB21: 0 | BC21: 0 | BD21: 0 | BE21: 0 | BF21: 0 | BG21: 0 | BH21: 0 | BI21: 0 | BJ21: 0 | BK21: 0 | BL21: 0 | BM21: 0 | BN21: 0 | BO21: 0 | BP21: 0 | BQ21: 0 | BR21: 0 | BS21: 0 | BT21: 0 | BU21: 0 | BV21: 0 | BW21: 0 | BX21: 0 | BY21: 0 | BZ21: 0 | CA21: 0 | CB21: 0 | CC21: 0 | CD21: 0 | CE21: 0 | CF21: 0 | CG21: 0 | CH21: 0 | CI21: 0 | CJ21: 0 | CK21: 0 | CL21: 0 | CM21: 0 | CN21: 0 | CO21: 0 | CP21: 0 | CQ21: 0 | CR21: 0 | CS21: 0 | CT21: 0 | CU21: 0 | CV21: 0 | CW21: 0 | CX21: 0 | CY21: 0 | CZ21: 0 | DA21: 0 | DB21: 0 | DC21: 0 | DD21: 0 | DE21: 0 | DF21: 0 | DG21: 0 | DH21: 0 | DI21: 0 | DJ21: 0 | DK21: 0 | DL21: 0 | DM21: 0 | DN21: 0 | DO21: 0 | DP21: 0 | DQ21: 0 | DR21: 0 | DS21: 0 | DT21: 0 | DU21: 0 | DV21: 0 | DW21: 0 | DX21: 0 | DY21: 0 | DZ21: 0 | EA21: 0 | EB21: 0 | EC21: 0 | ED21: 0 | EE21: 0 | EF21: 0 | EG21: 0 | EH21: =SUM(CP21:EG21) -> 0 | EK21: =SUM(DL21:EG21) -> 0 | ET21: =SUM(DT21:EG21) -> 0
A22: Informes de mitigación de vulnerabilidades o dictámenes técnicos en ciberseguridad | C22: 0 | D22: 0 | E22: 0 | F22: 0 | G22: 0 | H22: 0 | I22: 0 | J22: 0 | K22: 0 | L22: 0 | M22: 0 | N22: 0 | O22: 0 | P22: 0 | Q22: 0 | R22: 0 | S22: 0 | T22: 0 | U22: 0 | V22: 0 | W22: 0 | X22: 0 | Y22: 0 | Z22: 0 | AA22: 0 | AB22: 0 | AC22: 0 | AD22: 0 | AE22: 0 | AF22: 0 | AG22: 0 | AH22: 0 | AI22: 0 | AJ22: 0 | AK22: 0 | AL22: 0 | AM22: 0 | AN22: 0 | AO22: 0 | AP22: 0 | AQ22: 0 | AR22: 0 | AS22: 0 | AT22: 0 | AU22: 0 | AV22: 0 | AW22: 0 | AX22: 0 | AY22: 0 | AZ22: 0 | BA22: 0 | BB22: 0 | BC22: 0 | BD22: 0 | BE22: 0 | BF22: 0 | BG22: 0 | BH22: 0 | BI22: 0 | BJ22: 0 | BK22: 0 | BL22: 0 | BM22: 0 | BN22: 0 | BO22: 0 | BP22: 0 | BQ22: 0 | BR22: 0 | BS22: 0 | BT22: 0 | BU22: 0 | BV22: 0 | BW22: 0 | BX22: 0 | BY22: 0 | BZ22: 0 | CA22: 0 | CB22: 0 | CC22: 0 | CD22: 0 | CE22: 0 | CF22: 0 | CG22: 0 | CH22: 0 | CI22: 0 | CJ22: 0 | CK22: 0 | CL22: 0 | CM22: 0 | CN22: 0 | CO22: 0 | CP22: 0 | CQ22: 0 | CR22: 0 | CS22: 0 | CT22: 0 | CU22: 0 | CV22: 0 | CW22: 0 | CX22: 0 | CY22: 0 | CZ22: 0 | DA22: 0 | DB22: 0 | DC22: 0 | DD22: 0 | DE22: 0 | DF22: 0 | DG22: 0 | DH22: 0 | DI22: 0 | DJ22: 0 | DK22: 0 | DL22: 0 | DM22: 0 | DN22: 0 | DO22: 0 | DP22: 0 | DQ22: 0 | DR22: 0 | DS22: 0 | DT22: 0 | DU22: 0 | DV22: 0 | DW22: 0 | DX22: 0 | DY22: 2 | DZ22: 171 | EA22: 0 | EB22: 0 | EC22: 0 | ED22: 0 | EE22: 0 | EF22: 0 | EG22: 0 | EH22: =SUM(CP22:EG22) -> 173 | EK22: =SUM(DL22:EG22) -> 173 | ET22: =SUM(DT22:EG22) -> 173
A23: Investigaciones de ciberseguridad: | C23: 347 | D23: 216 | E23: 256 | F23: 200 | G23: 154 | H23: 152 | I23: 199 | J23: 130 | K23: 177 | L23: 306 | M23: 600 | N23: 203 | O23: 160 | P23: 153 | Q23: 119 | R23: 123 | S23: 44 | T23: 16 | U23: 80 | V23: 115 | W23: 123 | X23: 66 | Y23: 90 | Z23: 36 | AA23: 139 | AB23: 100 | AC23: 82 | AD23: 164 | AE23: 93 | AF23: 102 | AG23: 138 | AH23: 119 | AI23: 224 | AJ23: 154 | AK23: 141 | AL23: 99 | AM23: 94 | AN23: 121 | AO23: 158 | AP23: 108 | AQ23: 66 | AR23: 82 | AS23: 83 | AT23: 88 | AU23: 69 | AV23: 71 | AW23: 88 | AX23: 68 | AY23: 62 | AZ23: 35 | BA23: 45 | BB23: 36 | BC23: 37 | BD23: 28 | BE23: 38 | BF23: 40 | BG23: 31 | BH23: 30 | BI23: 40 | BJ23: 47 | BK23: 25 | BL23: 48 | BM23: 35 | BN23: 33 | BO23: 43 | BP23: 61 | BQ23: 35 | BR23: 26 | BS23: 20 | BT23: 33 | BU23: 43 | BV23: 29 | BW23: 23 | BX23: 50 | BY23: 31 | BZ23: 39 | CA23: 35 | CB23: 27 | CC23: 48 | CD23: 40 | CE23: 53 | CF23: 40 | CG23: 47 | CH23: 41 | CI23: 31 | CJ23: 33 | CK23: 57 | CL23: 25 | CM23: 68 | CN23: 50 | CO23: 48 | CP23: 35 | CQ23: 35 | CR23: 37 | CS23: 61 | CT23: 28 | CU23: 33 | CV23: 18 | CW23: 65 | CX23: 36 | CY23: 13 | CZ23: 59 | DA23: 23 | DB23: 39 | DC23: 44 | DD23: 37 | DE23: 37 | DF23: 56 | DG23: 38 | DH23: 56 | DI23: 25 | DJ23: 35 | DK23: 15 | DL23: =4+18 -> 22 | DM23: =3+37 -> 40 | DN23: =36+1 -> 37 | DO23: =32+1 -> 33 | DP23: 55 | DQ23: 17 | DR23: =2+25 -> 27 | DS23: =31+0 -> 31 | DT23: 1 | DU23: 2 | DV23: 0 | DW23: 1 | DX23: 0 | DY23: 0 | DZ23: 1 | EA23: 2 | EB23: 0 | EC23: 0 | ED23: 0 | EE23: 1 | EF23: 1 | EG23: 1 | EH23: =SUM(CP23:EG23) -> 1097 | EI23: =SUM(C23:DM23) -> 9289 | EJ23: =SUM(J23:DM23) -> 7765 | EK23: =SUM(DL23:EG23) -> 272 | EL23: =SUM(C23:C23) -> 347 | EM23: =SUM(D23:O23) -> 2753 | EN23: =SUM(P23:AA23) -> 1104 | EO23: =SUM(AB23:AM23) -> 1510 | EP23: =SUM(AN23:AY23) -> 1064 | EQ23: =SUM(AZ23:BW23) -> 861 | ER23: =SUM(BX23:CU23) -> 992 | ES23: =SUM(CV23:DS23) -> 858 | ET23: =SUM(DT23:EG23) -> 10 | EU23: =SUM(BP23:CK23) -> 842 | EV23: =SUM(CD23:CU23) -> 762 | EX23: =SUM(C23:CO23) -> 8402 | EY23: =SUM(F23:DK23) -> 8408 | EZ23: 816
A24: Ciberinvestigaciones | B24: Amenazas | C24: 18 | D24: 13 | E24: 10 | F24: 11 | G24: 6 | H24: 4 | I24: 7 | J24: 8 | K24: 8 | L24: 13 | M24: 13 | N24: 7 | O24: 7 | P24: 9 | Q24: 19 | R24: 7 | S24: 0 | T24: 0 | U24: 2 | V24: 3 | W24: 14 | X24: 0 | Y24: 5 | Z24: 0 | AA24: 5 | AB24: 1 | AC24: 1 | AD24: 4 | AE24: 3 | AF24: 9 | AG24: 7 | AH24: 2 | AI24: 6 | AJ24: 10 | AK24: 2 | AL24: 3 | AM24: 1 | AN24: 1 | AO24: 1 | AP24: 0 | AQ24: 0 | AR24: 0 | AS24: 1 | AT24: 0 | AU24: 0 | AV24: 1 | AW24: 1 | AX24: 0 | AY24: 2 | AZ24: 0 | BA24: 0 | BB24: 0 | BC24: 0 | BD24: 0 | BE24: 0 | BF24: 0 | BG24: 3 | BH24: 0 | BI24: 0 | BJ24: 1 | BK24: 0 | BL24: 0 | BM24: 0 | BN24: 0 | BO24: 0 | BP24: 2 | BQ24: 0 | BR24: 1 | BS24: 0 | BT24: 1 | BU24: 0 | BV24: 0 | BW24: 0 | BX24: 0 | BY24: 0 | BZ24: 0 | CA24: 0 | CB24: 0 | CC24: 1 | CD24: 0 | CE24: 0 | CF24: 0 | CG24: 0 | CH24: 0 | CI24: 0 | CJ24: 0 | CK24: 0 | CL24: 0 | CM24: 3 | CN24: 0 | CO24: 0 | CP24: 0 | CQ24: 0 | CR24: 0 | CS24: 0 | CT24: 0 | CU24: 1 | CV24: 0 | CW24: 1 | CX24: 0 | CY24: 0 | CZ24: 0 | DA24: 0 | DB24: 0 | DC24: 0 | DD24: 0 | DE24: 0 | DF24: 0 | DG24: 0 | DH24: 0 | DI24: 0 | DJ24: 0 | DK24: 0 | DL24: 0 | EH24: =SUM(CP24:EG24) -> 2 | EI24: =SUM(C24:DM24) -> 259 | EJ24: =SUM(J24:DM24) -> 190 | EK24: =SUM(DL24:EG24) -> 0 | EL24: =SUM(C24:C24) -> 18 | EM24: =SUM(D24:O24) -> 107 | EN24: =SUM(P24:AA24) -> 64 | EO24: =SUM(AB24:AM24) -> 49 | EP24: =SUM(AN24:AY24) -> 7 | EQ24: =SUM(AZ24:BW24) -> 8 | ER24: =SUM(BX24:CU24) -> 5 | ES24: =SUM(CV24:DS24) -> 1 | ET24: =SUM(DT24:EG24) -> 0 | EU24: =SUM(BP24:CK24) -> 5 | EV24: =SUM(CD24:CU24) -> 4 | EX24: =SUM(C24:CO24) -> 257 | EY24: =SUM(F24:DK24) -> 218
A25: Ciberinvestigaciones | B25: Desaparición Forzada | C25: 7 | D25: 2 | E25: 1 | F25: 6 | G25: 1 | H25: 4 | I25: 9 | J25: 2 | K25: 4 | L25: 13 | M25: 11 | N25: 4 | O25: 4 | P25: 6 | Q25: 8 | R25: 6 | S25: 3 | T25: 0 | U25: 3 | V25: 0 | W25: 7 | X25: 3 | Y25: 1 | Z25: 0 | AA25: 3 | AB25: 1 | AC25: 1 | AD25: 4 | AE25: 1 | AF25: 6 | AG25: 4 | AH25: 10 | AI25: 12 | AJ25: 2 | AK25: 1 | AL25: 6 | AM25: 5 | AN25: 2 | AO25: 23 | AP25: 12 | AQ25: 3 | AR25: 9 | AS25: 8 | AT25: 8 | AU25: 3 | AV25: 5 | AW25: 2 | AX25: 0 | AY25: 3 | AZ25: 1 | BA25: 1 | BB25: 0 | BC25: 0 | BD25: 0 | BE25: 2 | BF25: 0 | BG25: 0 | BH25: 0 | BI25: 2 | BJ25: 1 | BK25: 1 | BL25: 2 | BM25: 1 | BN25: 1 | BO25: 0 | BP25: 3 | BQ25: 0 | BR25: 0 | BS25: 3 | BT25: 1 | BU25: 4 | BV25: 3 | BW25: 1 | BX25: 11 | BY25: 2 | BZ25: 1 | CA25: 13 | CB25: 1 | CC25: 11 | CD25: 8 | CE25: 8 | CF25: 8 | CG25: 3 | CH25: 10 | CI25: 5 | CJ25: 1 | CK25: 7 | CL25: 0 | CM25: 16 | CN25: 17 | CO25: 4 | CP25: 5 | CQ25: 7 | CR25: 11 | CS25: 4 | CT25: 1 | CU25: 13 | CV25: 0 | CW25: 5 | CX25: 5 | CY25: 0 | CZ25: 27 | DA25: 7 | DB25: 10 | DC25: 13 | DD25: 11 | DE25: 13 | DF25: 17 | DG25: 18 | DH25: 10 | DI25: 0 | DJ25: 12 | DK25: 3 | DL25: 0 | EH25: =SUM(CP25:EG25) -> 192 | EI25: =SUM(C25:DM25) -> 584 | EJ25: =SUM(J25:DM25) -> 554 | EK25: =SUM(DL25:EG25) -> 0 | EL25: =SUM(C25:C25) -> 7 | EM25: =SUM(D25:O25) -> 61 | EN25: =SUM(P25:AA25) -> 40 | EO25: =SUM(AB25:AM25) -> 53 | EP25: =SUM(AN25:AY25) -> 78 | EQ25: =SUM(AZ25:BW25) -> 27 | ER25: =SUM(BX25:CU25) -> 167 | ES25: =SUM(CV25:DS25) -> 151 | ET25: =SUM(DT25:EG25) -> 0 | EU25: =SUM(BP25:CK25) -> 104 | EV25: =SUM(CD25:CU25) -> 128 | EX25: =SUM(C25:CO25) -> 392 | EY25: =SUM(F25:DK25) -> 574
A26: Ciberinvestigaciones | B26: Fraude | C26: 28 | D26: 11 | E26: 17 | F26: 21 | G26: 20 | H26: 8 | I26: 15 | J26: 8 | K26: 10 | L26: 6 | M26: 18 | N26: 14 | O26: 8 | P26: 4 | Q26: 9 | R26: 5 | S26: 3 | T26: 1 | U26: 1 | V26: 0 | W26: 1 | X26: 1 | Y26: 5 | Z26: 2 | AA26: 6 | AB26: 6 | AC26: 2 | AD26: 3 | AE26: 6 | AF26: 6 | AG26: 7 | AH26: 14 | AI26: 9 | AJ26: 9 | AK26: 7 | AL26: 0 | AM26: 5 | AN26: 4 | AO26: 13 | AP26: 9 | AQ26: 6 | AR26: 2 | AS26: 9 | AT26: 15 | AU26: 7 | AV26: 6 | AW26: 5 | AX26: 4 | AY26: 1 | AZ26: 2 | BA26: 0 | BB26: 5 | BC26: 3 | BD26: 3 | BE26: 6 | BF26: 5 | BG26: 0 | BH26: 0 | BI26: 0 | BJ26: 7 | BK26: 2 | BL26: 5 | BM26: 3 | BN26: 0 | BO26: 3 | BP26: 4 | BQ26: 1 | BR26: 1 | BS26: 2 | BT26: 0 | BU26: 1 | BV26: 0 | BW26: 0 | BX26: 5 | BY26: 3 | BZ26: 2 | CA26: 1 | CB26: 1 | CC26: 1 | CD26: 2 | CE26: 2 | CF26: 1 | CG26: 4 | CH26: 0 | CI26: 0 | CJ26: 2 | CK26: 2 | CL26: 1 | CM26: 4 | CN26: 1 | CO26: 3 | CP26: 2 | CQ26: 1 | CR26: 3 | CS26: 2 | CT26: 1 | CU26: 6 | CV26: 1 | CW26: 4 | CX26: 1 | CY26: 0 | CZ26: 1 | DA26: 0 | DB26: 0 | DC26: 1 | DD26: 0 | DE26: 0 | DF26: 0 | DG26: 1 | DH26: 0 | DI26: 0 | DJ26: 0 | DK26: 0 | DL26: 0 | EH26: =SUM(CP26:EG26) -> 24 | EI26: =SUM(C26:DM26) -> 489 | EJ26: =SUM(J26:DM26) -> 369 | EK26: =SUM(DL26:EG26) -> 0 | EL26: =SUM(C26:C26) -> 28 | EM26: =SUM(D26:O26) -> 156 | EN26: =SUM(P26:AA26) -> 38 | EO26: =SUM(AB26:AM26) -> 74 | EP26: =SUM(AN26:AY26) -> 81 | EQ26: =SUM(AZ26:BW26) -> 53 | ER26: =SUM(BX26:CU26) -> 50 | ES26: =SUM(CV26:DS26) -> 9 | ET26: =SUM(DT26:EG26) -> 0 | EU26: =SUM(BP26:CK26) -> 35 | EV26: =SUM(CD26:CU26) -> 37 | EX26: =SUM(C26:CO26) -> 465 | EY26: =SUM(F26:DK26) -> 433
A27: Ciberinvestigaciones | B27: Personas Desaparecidas | C27: 25 | D27: 25 | E27: 24 | F27: 15 | G27: 18 | H27: 24 | I27: 31 | J27: 12 | K27: 24 | L27: 43 | M27: 59 | N27: 13 | O27: 7 | P27: 14 | Q27: 9 | R27: 7 | S27: 3 | T27: 0 | U27: 5 | V27: 1 | W27: 10 | X27: 4 | Y27: 15 | Z27: 3 | AA27: 2 | AB27: 10 | AC27: 7 | AD27: 9 | AE27: 18 | AF27: 10 | AG27: 8 | AH27: 20 | AI27: 7 | AJ27: 7 | AK27: 3 | AL27: 2 | AM27: 2 | AN27: 9 | AO27: 12 | AP27: 5 | AQ27: 8 | AR27: 15 | AS27: 8 | AT27: 5 | AU27: 12 | AV27: 3 | AW27: 9 | AX27: 4 | AY27: 6 | AZ27: 1 | BA27: 7 | BB27: 2 | BC27: 3 | BD27: 0 | BE27: 0 | BF27: 8 | BG27: 3 | BH27: 1 | BI27: 1 | BJ27: 0 | BK27: 2 | BL27: 5 | BM27: 0 | BN27: 1 | BO27: 2 | BP27: 1 | BQ27: 5 | BR27: 4 | BS27: 1 | BT27: 0 | BU27: 1 | BV27: 2 | BW27: 3 | BX27: 4 | BY27: 4 | BZ27: 1 | CA27: 0 | CB27: 0 | CC27: 2 | CD27: 2 | CE27: 1 | CF27: 0 | CG27: 2 | CH27: 0 | CI27: 0 | CJ27: 1 | CK27: 0 | CL27: 0 | CM27: 6 | CN27: 2 | CO27: 6 | CP27: 0 | CQ27: 1 | CR27: 1 | CS27: 2 | CT27: 2 | CU27: 0 | CV27: 0 | CW27: 5 | CX27: 0 | CY27: 0 | CZ27: 2 | DA27: 0 | DB27: 2 | DC27: 1 | DD27: 1 | DE27: 1 | DF27: 4 | DG27: 2 | DH27: 1 | DI27: 0 | DJ27: 3 | DK27: 0 | DL27: 0 | EH27: =SUM(CP27:EG27) -> 28 | EI27: =SUM(C27:DM27) -> 704 | EJ27: =SUM(J27:DM27) -> 542 | EK27: =SUM(DL27:EG27) -> 0 | EL27: =SUM(C27:C27) -> 25 | EM27: =SUM(D27:O27) -> 295 | EN27: =SUM(P27:AA27) -> 73 | EO27: =SUM(AB27:AM27) -> 103 | EP27: =SUM(AN27:AY27) -> 96 | EQ27: =SUM(AZ27:BW27) -> 53 | ER27: =SUM(BX27:CU27) -> 37 | ES27: =SUM(CV27:DS27) -> 22 | ET27: =SUM(DT27:EG27) -> 0 | EU27: =SUM(BP27:CK27) -> 34 | EV27: =SUM(CD27:CU27) -> 26 | EX27: =SUM(C27:CO27) -> 676 | EY27: =SUM(F27:DK27) -> 630
A28: Ciberinvestigaciones | B28: Pornografía Infantil | C28: 23 | D28: 57 | E28: 41 | F28: 30 | G28: 11 | H28: 25 | I28: 19 | J28: 18 | K28: 6 | L28: 50 | M28: 306 | N28: 24 | O28: 40 | P28: 17 | Q28: 1 | R28: 28 | S28: 13 | T28: 4 | U28: 23 | V28: 49 | W28: 8 | X28: 16 | Y28: 10 | Z28: 12 | AA28: 59 | AB28: 44 | AC28: 23 | AD28: 84 | AE28: 17 | AF28: 18 | AG28: 37 | AH28: 14 | AI28: 90 | AJ28: 74 | AK28: 74 | AL28: 25 | AM28: 23 | AN28: 13 | AO28: 32 | AP28: 41 | AQ28: 11 | AR28: 14 | AS28: 12 | AT28: 20 | AU28: 11 | AV28: 17 | AW28: 9 | AX28: 14 | AY28: 14 | AZ28: 8 | BA28: 6 | BB28: 9 | BC28: 8 | BD28: 7 | BE28: 8 | BF28: 9 | BG28: 11 | BH28: 11 | BI28: 6 | BJ28: 11 | BK28: 8 | BL28: 10 | BM28: 12 | BN28: 4 | BO28: 15 | BP28: 10 | BQ28: 11 | BR28: 5 | BS28: 3 | BT28: 8 | BU28: 12 | BV28: 10 | BW28: 3 | BX28: 4 | BY28: 7 | BZ28: 9 | CA28: 4 | CB28: 5 | CC28: 11 | CD28: 7 | CE28: 5 | CF28: 7 | CG28: 10 | CH28: 8 | CI28: 11 | CJ28: 6 | CK28: 8 | CL28: 5 | CM28: 8 | CN28: 11 | CO28: 9 | CP28: 11 | CQ28: 10 | CR28: 4 | CS28: 25 | CT28: 8 | CU28: 2 | CV28: 2 | CW28: 11 | CX28: 9 | CY28: 3 | CZ28: 12 | DA28: 4 | DB28: 9 | DC28: 5 | DD28: 2 | DE28: 11 | DF28: 5 | DG28: 3 | DH28: 16 | DI28: 10 | DJ28: 0 | DK28: 2 | DL28: 18 | EH28: =SUM(CP28:EG28) -> 182 | EI28: =SUM(C28:DM28) -> 2143 | EJ28: =SUM(J28:DM28) -> 1937 | EK28: =SUM(DL28:EG28) -> 18 | EL28: =SUM(C28:C28) -> 23 | EM28: =SUM(D28:O28) -> 627 | EN28: =SUM(P28:AA28) -> 240 | EO28: =SUM(AB28:AM28) -> 523 | EP28: =SUM(AN28:AY28) -> 208 | EQ28: =SUM(AZ28:BW28) -> 205 | ER28: =SUM(BX28:CU28) -> 195 | ES28: =SUM(CV28:DS28) -> 122 | ET28: =SUM(DT28:EG28) -> 0 | EU28: =SUM(BP28:CK28) -> 164 | EV28: =SUM(CD28:CU28) -> 155 | EX28: =SUM(C28:CO28) -> 1961 | EY28: =SUM(F28:DK28) -> 2004
A29: Ciberinvestigaciones | B29: Secuestro | C29: 73 | D29: 0 | E29: 37 | F29: 33 | G29: 30 | H29: 31 | I29: 27 | J29: 14 | K29: 50 | L29: 78 | M29: 31 | N29: 49 | O29: 30 | P29: 31 | Q29: 12 | R29: 7 | S29: 2 | T29: 0 | U29: 11 | V29: 0 | W29: 18 | X29: 3 | Y29: 7 | Z29: 2 | AA29: 8 | AB29: 6 | AC29: 0 | AD29: 4 | AE29: 1 | AF29: 4 | AG29: 5 | AH29: 14 | AI29: 7 | AJ29: 8 | AK29: 3 | AL29: 1 | AM29: 2 | AN29: 8 | AO29: 7 | AP29: 5 | AQ29: 3 | AR29: 2 | AS29: 2 | AT29: 2 | AU29: 0 | AV29: 4 | AW29: 1 | AX29: 1 | AY29: 0 | AZ29: 2 | BA29: 2 | BB29: 2 | BC29: 2 | BD29: 1 | BE29: 0 | BF29: 0 | BG29: 1 | BH29: 1 | BI29: 2 | BJ29: 0 | BK29: 0 | BL29: 1 | BM29: 2 | BN29: 3 | BO29: 2 | BP29: 3 | BQ29: 5 | BR29: 2 | BS29: 1 | BT29: 0 | BU29: 4 | BV29: 0 | BW29: 0 | BX29: 1 | BY29: 0 | BZ29: 0 | CA29: 1 | CB29: 0 | CC29: 0 | CD29: 2 | CE29: 2 | CF29: 0 | CG29: 0 | CH29: 4 | CI29: 0 | CJ29: 3 | CK29: 2 | CL29: 0 | CM29: 0 | CN29: 1 | CO29: 3 | CP29: 1 | CQ29: 0 | CR29: 0 | CS29: 0 | CT29: 3 | CU29: 0 | CV29: 0 | CW29: 1 | CX29: 1 | CY29: 0 | CZ29: 0 | DA29: 0 | DB29: 0 | DC29: 0 | DD29: 0 | DE29: 1 | DF29: 0 | DG29: 2 | DH29: 2 | DI29: 0 | DJ29: 0 | DK29: 0 | DL29: 0 | EH29: =SUM(CP29:EG29) -> 11 | EI29: =SUM(C29:DM29) -> 740 | EJ29: =SUM(J29:DM29) -> 509 | EK29: =SUM(DL29:EG29) -> 0 | EL29: =SUM(C29:C29) -> 73 | EM29: =SUM(D29:O29) -> 410 | EN29: =SUM(P29:AA29) -> 101 | EO29: =SUM(AB29:AM29) -> 55 | EP29: =SUM(AN29:AY29) -> 35 | EQ29: =SUM(AZ29:BW29) -> 36 | ER29: =SUM(BX29:CU29) -> 23 | ES29: =SUM(CV29:DS29) -> 7 | ET29: =SUM(DT29:EG29) -> 0 | EU29: =SUM(BP29:CK29) -> 30 | EV29: =SUM(CD29:CU29) -> 21 | EX29: =SUM(C29:CO29) -> 729 | EY29: =SUM(F29:DK29) -> 630
A30: Ciberinvestigaciones | B30: Trata de Personas | C30: 37 | D30: 20 | E30: 20 | F30: 14 | G30: 5 | H30: 12 | I30: 20 | J30: 19 | K30: 14 | L30: 12 | M30: 66 | N30: 25 | O30: 20 | P30: 22 | Q30: 14 | R30: 12 | S30: 0 | T30: 7 | U30: 14 | V30: 39 | W30: 9 | X30: 12 | Y30: 12 | Z30: 5 | AA30: 18 | AB30: 6 | AC30: 32 | AD30: 10 | AE30: 7 | AF30: 18 | AG30: 11 | AH30: 5 | AI30: 31 | AJ30: 6 | AK30: 17 | AL30: 9 | AM30: 4 | AN30: 0 | AO30: 20 | AP30: 3 | AQ30: 4 | AR30: 3 | AS30: 8 | AT30: 1 | AU30: 8 | AV30: 2 | AW30: 3 | AX30: 2 | AY30: 6 | AZ30: 1 | BA30: 4 | BB30: 2 | BC30: 6 | BD30: 3 | BE30: 1 | BF30: 0 | BG30: 2 | BH30: 1 | BI30: 5 | BJ30: 6 | BK30: 1 | BL30: 1 | BM30: 0 | BN30: 0 | BO30: 0 | BP30: 1 | BQ30: 1 | BR30: 0 | BS30: 1 | BT30: 0 | BU30: 0 | BV30: 0 | BW30: 0 | BX30: 0 | BY30: 0 | BZ30: 0 | CA30: 0 | CB30: 0 | CC30: 0 | CD30: 0 | CE30: 2 | CF30: 0 | CG30: 1 | CH30: 0 | CI30: 0 | CJ30: 0 | CK30: 0 | CL30: 0 | CM30: 0 | CN30: 0 | CO30: 0 | CP30: 0 | CQ30: 0 | CR30: 0 | CS30: 0 | CT30: 1 | CU30: 0 | CV30: 2 | CW30: 1 | CX30: 0 | CY30: 0 | CZ30: 1 | DA30: 1 | DB30: 0 | DC30: 0 | DD30: 1 | DE30: 1 | DF30: 0 | DG30: 0 | DH30: 0 | DI30: 0 | DJ30: 0 | DK30: 0 | DL30: 0 | EH30: =SUM(CP30:EG30) -> 8 | EI30: =SUM(C30:DM30) -> 711 | EJ30: =SUM(J30:DM30) -> 583 | EK30: =SUM(DL30:EG30) -> 0 | EL30: =SUM(C30:C30) -> 37 | EM30: =SUM(D30:O30) -> 247 | EN30: =SUM(P30:AA30) -> 164 | EO30: =SUM(AB30:AM30) -> 156 | EP30: =SUM(AN30:AY30) -> 60 | EQ30: =SUM(AZ30:BW30) -> 36 | ER30: =SUM(BX30:CU30) -> 4 | ES30: =SUM(CV30:DS30) -> 7 | ET30: =SUM(DT30:EG30) -> 0 | EU30: =SUM(BP30:CK30) -> 6 | EV30: =SUM(CD30:CU30) -> 4 | EX30: =SUM(C30:CO30) -> 703 | EY30: =SUM(F30:DK30) -> 634
A31: Ciberinvestigaciones | B31: Menor desaparecido | C31: 0 | D31: 0 | E31: 0 | F31: 0 | G31: 0 | H31: 0 | I31: 0 | J31: 0 | K31: 0 | L31: 0 | M31: 0 | N31: 0 | O31: 0 | P31: 0 | Q31: 0 | R31: 0 | S31: 0 | T31: 0 | U31: 0 | V31: 1 | W31: 1 | X31: 0 | Y31: 0 | Z31: 0 | AA31: 2 | AB31: 2 | AC31: 0 | AD31: 0 | AE31: 0 | AF31: 0 | AG31: 5 | AH31: 0 | AI31: 1 | AJ31: 0 | AK31: 2 | AL31: 1 | AM31: 0 | AN31: 0 | AO31: 2 | AP31: 0 | AQ31: 0 | AR31: 5 | AS31: 0 | AT31: 1 | AU31: 0 | AV31: 3 | AW31: 6 | AX31: 5 | AY31: 2 | AZ31: 2 | BA31: 1 | BB31: 1 | BC31: 2 | BD31: 2 | BE31: 3 | BF31: 2 | BG31: 0 | BH31: 0 | BI31: 1 | BJ31: 0 | BK31: 1 | BL31: 0 | BM31: 1 | BN31: 1 | BO31: 3 | BP31: 0 | BQ31: 0 | BR31: 1 | BS31: 0 | BT31: 1 | BU31: 0 | BV31: 0 | BW31: 0 | BX31: 0 | BY31: 0 | BZ31: 1 | CA31: 0 | CB31: 0 | CC31: 0 | CD31: 0 | CE31: 0 | CF31: 0 | CG31: 0 | CH31: 0 | CI31: 0 | CJ31: 0 | CK31: 0 | CL31: 0 | CM31: 0 | CN31: 0 | CO31: 0 | CP31: 0 | CQ31: 0 | CR31: 0 | CS31: 0 | CT31: 0 | CU31: 1 | CV31: 0 | CW31: 0 | CX31: 0 | CY31: 0 | CZ31: 0 | DA31: 0 | DB31: 0 | DC31: 0 | DD31: 0 | DE31: 0 | DF31: 0 | DG31: 0 | DH31: 0 | DI31: 0 | DJ31: 0 | DK31: 0 | DL31: 0 | EH31: =SUM(CP31:EG31) -> 1 | EI31: =SUM(C31:DM31) -> 63 | EJ31: =SUM(J31:DM31) -> 63 | EK31: =SUM(DL31:EG31) -> 0 | EL31: =SUM(C31:C31) -> 0 | EM31: =SUM(D31:O31) -> 0 | EN31: =SUM(P31:AA31) -> 4 | EO31: =SUM(AB31:AM31) -> 11 | EP31: =SUM(AN31:AY31) -> 24 | EQ31: =SUM(AZ31:BW31) -> 22 | ER31: =SUM(BX31:CU31) -> 2 | ES31: =SUM(CV31:DS31) -> 0 | ET31: =SUM(DT31:EG31) -> 0 | EU31: =SUM(BP31:CK31) -> 3 | EV31: =SUM(CD31:CU31) -> 1 | EX31: =SUM(C31:CO31) -> 62 | EY31: =SUM(F31:DK31) -> 63
A32: Ciberinvestigaciones | B32: Trafico de personas (migrantes) | C32: 0 | D32: 0 | E32: 0 | F32: 0 | G32: 0 | H32: 0 | I32: 0 | J32: 0 | K32: 0 | L32: 0 | M32: 0 | N32: 0 | O32: 0 | P32: 0 | Q32: 0 | R32: 0 | S32: 0 | T32: 0 | U32: 0 | V32: 0 | W32: 0 | X32: 0 | Y32: 0 | Z32: 0 | AA32: 0 | AB32: 0 | AC32: 0 | AD32: 0 | AE32: 0 | AF32: 0 | AG32: 0 | AH32: 0 | AI32: 0 | AJ32: 0 | AK32: 0 | AL32: 0 | AM32: 0 | AN32: 0 | AO32: 0 | AP32: 0 | AQ32: 0 | AR32: 0 | AS32: 1 | AT32: 0 | AU32: 0 | AV32: 0 | AW32: 4 | AX32: 8 | AY32: 0 | AZ32: 7 | BA32: 8 | BB32: 5 | BC32: 2 | BD32: 6 | BE32: 4 | BF32: 3 | BG32: 0 | BH32: 0 | BI32: 6 | BJ32: 3 | BK32: 1 | BL32: 3 | BM32: 9 | BN32: 9 | BO32: 2 | BP32: 19 | BQ32: 1 | BR32: 3 | BS32: 0 | BT32: 9 | BU32: 8 | BV32: 9 | BW32: 4 | BX32: 11 | BY32: 7 | BZ32: 10 | CA32: 5 | CB32: 9 | CC32: 5 | CD32: 8 | CE32: 14 | CF32: 11 | CG32: 16 | CH32: 9 | CI32: 6 | CJ32: 11 | CK32: 10 | CL32: 15 | CM32: 4 | CN32: 7 | CO32: 6 | CP32: 6 | CQ32: 5 | CR32: 9 | CS32: 12 | CT32: 5 | CU32: 7 | CV32: 8 | CW32: 16 | CX32: 8 | CY32: 9 | CZ32: 3 | DA32: 6 | DB32: 8 | DC32: 16 | DD32: 9 | DE32: 3 | DF32: 6 | DG32: 4 | DH32: 17 | DI32: 10 | DJ32: 0 | DK32: 0 | DL32: 0 | EH32: =SUM(CP32:EG32) -> 167 | EI32: =SUM(C32:DM32) -> 465 | EJ32: =SUM(J32:DM32) -> 465 | EK32: =SUM(DL32:EG32) -> 0 | EL32: =SUM(C32:C32) -> 0 | EM32: =SUM(D32:O32) -> 0 | EN32: =SUM(P32:AA32) -> 0 | EO32: =SUM(AB32:AM32) -> 0 | EP32: =SUM(AN32:AY32) -> 13 | EQ32: =SUM(AZ32:BW32) -> 121 | ER32: =SUM(BX32:CU32) -> 208 | ES32: =SUM(CV32:DS32) -> 123 | ET32: =SUM(DT32:EG32) -> 0 | EU32: =SUM(BP32:CK32) -> 185 | EV32: =SUM(CD32:CU32) -> 161 | EX32: =SUM(C32:CO32) -> 298 | EY32: =SUM(F32:DK32) -> 465
A33: Ciberinvestigaciones | B33: Delincuencia Organizada | C33: 13 | D33: 3 | E33: 16 | F33: 8 | G33: 5 | H33: 8 | I33: 5 | J33: 0 | K33: 6 | L33: 8 | M33: 2 | N33: 6 | O33: 6 | P33: 5 | Q33: 5 | R33: 4 | S33: 0 | T33: 0 | U33: 2 | V33: 0 | W33: 5 | X33: 1 | Y33: 1 | Z33: 0 | AA33: 1 | AB33: 1 | AC33: 0 | AD33: 5 | AE33: 3 | AF33: 4 | AG33: 2 | AH33: 10 | AI33: 3 | AJ33: 8 | AK33: 4 | AL33: 5 | AM33: 4 | AN33: 3 | AO33: 2 | AP33: 2 | AQ33: 1 | AR33: 0 | AS33: 2 | AT33: 3 | AU33: 0 | AV33: 3 | AW33: 2 | AX33: 0 | AY33: 1 | AZ33: 0 | BA33: 0 | BB33: 0 | BC33: 0 | BD33: 0 | BE33: 0 | BF33: 0 | BG33: 0 | BH33: 0 | BI33: 0 | BJ33: 0 | BK33: 0 | BL33: 1 | BM33: 0 | BN33: 0 | BO33: 0 | BP33: 0 | BQ33: 0 | BR33: 0 | BS33: 0 | BT33: 0 | BU33: 0 | BV33: 0 | BW33: 1 | BX33: 1 | BY33: 0 | BZ33: 1 | CA33: 1 | CB33: 1 | CC33: 2 | CD33: 1 | CE33: 0 | CG33: 1 | CH33: 1 | CI33: 1 | CJ33: 1 | CK33: 1 | CL33: 0 | CM33: 2 | CN33: 1 | CO33: 0 | CP33: 0 | CQ33: 0 | CR33: 0 | CS33: 1 | CT33: 0 | CU33: 0 | CV33: 1 | CW33: 6 | CX33: 2 | CY33: 0 | CZ33: 1 | DA33: 0 | DB33: 0 | DC33: 0 | DD33: 3 | DE33: 0 | DF33: 1 | DG33: 0 | DH33: 1 | DI33: 0 | DJ33: 0 | DK33: 0 | DL33: 0 | EH33: =SUM(CP33:EG33) -> 16 | EI33: =SUM(C33:DM33) -> 211 | EJ33: =SUM(J33:DM33) -> 153 | EK33: =SUM(DL33:EG33) -> 0 | EL33: =SUM(C33:C33) -> 13 | EM33: =SUM(D33:O33) -> 73 | EN33: =SUM(P33:AA33) -> 24 | EO33: =SUM(AB33:AM33) -> 49 | EP33: =SUM(AN33:AY33) -> 19 | EQ33: =SUM(AZ33:BW33) -> 2 | ER33: =SUM(BX33:CU33) -> 16 | ES33: =SUM(CV33:DS33) -> 15 | ET33: =SUM(DT33:EG33) -> 0 | EU33: =SUM(BP33:CK33) -> 13 | EV33: =SUM(CD33:CU33) -> 10 | EX33: =SUM(C33:CO33) -> 195 | EY33: =SUM(F33:DK33) -> 179
A34: Ciberinvestigaciones | B34: Extorsión | C34: 17 | D34: 2 | E34: 20 | F34: 6 | G34: 6 | H34: 2 | I34: 4 | J34: 1 | K34: 6 | L34: 11 | M34: 8 | N34: 6 | O34: 2 | P34: 4 | Q34: 4 | R34: 0 | S34: 2 | T34: 0 | U34: 1 | V34: 1 | W34: 3 | X34: 0 | Y34: 5 | Z34: 0 | AA34: 0 | AB34: 0 | AC34: 0 | AD34: 0 | AE34: 0 | AF34: 0 | AG34: 1 | AH34: 2 | AI34: 4 | AJ34: 5 | AK34: 0 | AL34: 1 | AM34: 1 | AN34: 3 | AO34: 2 | AP34: 1 | AQ34: 1 | AR34: 1 | AS34: 0 | AT34: 1 | AU34: 3 | AV34: 3 | AW34: 4 | AX34: 5 | AY34: 3 | AZ34: 0 | BA34: 1 | BB34: 0 | BC34: 1 | BD34: 0 | BE34: 0 | BF34: 1 | BG34: 1 | BH34: 0 | BI34: 1 | BJ34: 0 | BK34: 0 | BL34: 0 | BM34: 0 | BN34: 1 | BO34: 0 | BP34: 0 | BQ34: 1 | BR34: 1 | BS34: 0 | BT34: 0 | BU34: 0 | BV34: 1 | BW34: 1 | BX34: 0 | BY34: 0 | BZ34: 0 | CA34: 0 | CB34: 0 | CC34: 1 | CD34: 0 | CE34: 1 | CF34: 0 | CG34: 0 | CH34: 0 | CI34: 0 | CJ34: 1 | CK34: 1 | CL34: 0 | CM34: 3 | CN34: 2 | CO34: 1 | CP34: 1 | CQ34: 1 | CR34: 0 | CS34: 0 | CT34: 0 | CU34: 1 | CV34: 0 | CW34: 0 | CX34: 1 | CY34: 0 | CZ34: 0 | DA34: 1 | DB34: 0 | DC34: 0 | DD34: 1 | DE34: 0 | DF34: 1 | DG34: 0 | DH34: 0 | DI34: 0 | DJ34: 0 | DK34: 0 | DL34: 0 | EH34: =SUM(CP34:EG34) -> 7 | EI34: =SUM(C34:DM34) -> 179 | EJ34: =SUM(J34:DM34) -> 122 | EK34: =SUM(DL34:EG34) -> 0 | EL34: =SUM(C34:C34) -> 17 | EM34: =SUM(D34:O34) -> 74 | EN34: =SUM(P34:AA34) -> 20 | EO34: =SUM(AB34:AM34) -> 14 | EP34: =SUM(AN34:AY34) -> 27 | EQ34: =SUM(AZ34:BW34) -> 10 | ER34: =SUM(BX34:CU34) -> 13 | ES34: =SUM(CV34:DS34) -> 4 | ET34: =SUM(DT34:EG34) -> 0 | EU34: =SUM(BP34:CK34) -> 8 | EV34: =SUM(CD34:CU34) -> 12 | EX34: =SUM(C34:CO34) -> 172 | EY34: =SUM(F34:DK34) -> 140
A35: Ciberinvestigaciones | B35: Delitos contra la Libertad de Expresión | C35: 10 | D35: 5 | E35: 9 | F35: 2 | G35: 4 | H35: 11 | I35: 5 | J35: 2 | K35: 5 | L35: 14 | M35: 7 | N35: 7 | O35: 8 | P35: 15 | Q35: 2 | R35: 2 | S35: 1 | T35: 0 | U35: 0 | V35: 6 | W35: 5 | X35: 3 | Y35: 6 | Z35: 2 | AA35: 0 | AB35: 3 | AC35: 0 | AD35: 3 | AE35: 3 | AF35: 3 | AG35: 0 | AH35: 0 | AI35: 1 | AJ35: 0 | AK35: 0 | AL35: 1 | AM35: 0 | AN35: 0 | AO35: 0 | AP35: 0 | AQ35: 0 | AR35: 0 | AS35: 0 | AT35: 0 | AU35: 0 | AV35: 0 | AW35: 0 | AX35: 0 | AY35: 0 | AZ35: 0 | BA35: 0 | BB35: 0 | BC35: 0 | BD35: 0 | BE35: 0 | BF35: 0 | BG35: 0 | BH35: 0 | BI35: 0 | BJ35: 0 | BK35: 0 | BL35: 0 | BM35: 0 | BN35: 0 | BO35: 0 | BP35: 0 | BQ35: 0 | BR35: 0 | BS35: 0 | BT35: 0 | BU35: 0 | BV35: 0 | BW35: 0 | BX35: 0 | BY35: 0 | BZ35: 0 | CA35: 0 | CB35: 0 | CC35: 0 | CD35: 0 | CE35: 0 | CF35: 0 | CG35: 0 | CH35: 0 | CI35: 0 | CJ35: 0 | CK35: 0 | CL35: 0 | CM35: 1 | CN35: 0 | CO35: 0 | CP35: 1 | CQ35: 0 | CR35: 0 | CS35: 0 | CT35: 0 | CU35: 0 | CV35: 0 | CW35: 0 | CX35: 0 | CY35: 0 | CZ35: 0 | DA35: 0 | DB35: 0 | DC35: 0 | DD35: 0 | DE35: 0 | DF35: 1 | DG35: 0 | DH35: 1 | DI35: 0 | DJ35: 0 | DK35: 0 | DL35: 0 | EH35: =SUM(CP35:EG35) -> 3 | EI35: =SUM(C35:DM35) -> 149 | EJ35: =SUM(J35:DM35) -> 103 | EK35: =SUM(DL35:EG35) -> 0 | EL35: =SUM(C35:C35) -> 10 | EM35: =SUM(D35:O35) -> 79 | EN35: =SUM(P35:AA35) -> 42 | EO35: =SUM(AB35:AM35) -> 14 | EP35: =SUM(AN35:AY35) -> 0 | EQ35: =SUM(AZ35:BW35) -> 0 | ER35: =SUM(BX35:CU35) -> 2 | ES35: =SUM(CV35:DS35) -> 2 | ET35: =SUM(DT35:EG35) -> 0 | EU35: =SUM(BP35:CK35) -> 0 | EV35: =SUM(CD35:CU35) -> 2 | EX35: =SUM(C35:CO35) -> 146 | EY35: =SUM(F35:DK35) -> 125
A36: Ciberinvestigaciones | B36: Homicidios | C36: 12 | D36: 12 | E36: 13 | F36: 5 | G36: 8 | H36: 0 | I36: 7 | J36: 5 | K36: 2 | L36: 4 | M36: 1 | N36: 3 | O36: 2 | P36: 1 | Q36: 1 | R36: 1 | S36: 1 | T36: 0 | U36: 0 | V36: 0 | W36: 1 | X36: 0 | Y36: 0 | Z36: 0 | AA36: 0 | AB36: 0 | AC36: 0 | AD36: 0 | AE36: 0 | AF36: 0 | AG36: 2 | AH36: 0 | AI36: 4 | AJ36: 4 | AK36: 5 | AL36: 1 | AM36: 1 | AN36: 4 | AO36: 2 | AP36: 0 | AQ36: 2 | AR36: 3 | AS36: 0 | AT36: 2 | AU36: 2 | AV36: 3 | AW36: 1 | AX36: 1 | AY36: 4 | AZ36: 0 | BA36: 1 | BB36: 0 | BC36: 0 | BD36: 0 | BE36: 0 | BF36: 0 | BG36: 0 | BH36: 3 | BI36: 0 | BJ36: 3 | BK36: 1 | BL36: 2 | BM36: 0 | BN36: 0 | BO36: 1 | BP36: 1 | BQ36: 0 | BR36: 0 | BS36: 2 | BT36: 0 | BU36: 1 | BV36: 0 | BW36: 0 | BX36: 1 | BY36: 0 | BZ36: 1 | CA36: 0 | CB36: 1 | CC36: 0 | CD36: 0 | CE36: 1 | CF36: 0 | CG36: 1 | CH36: 0 | CI36: 0 | CJ36: 0 | CK36: 4 | CL36: 0 | CM36: 0 | CN36: 0 | CO36: 1 | CP36: 0 | CQ36: 1 | CR36: 0 | CS36: 0 | CT36: 0 | CU36: 0 | CV36: 0 | CW36: 0 | CX36: 0 | CY36: 0 | CZ36: 1 | DA36: 1 | DB36: 1 | DC36: 0 | DD36: 0 | DE36: 1 | DF36: 0 | DG36: 1 | DH36: 1 | DI36: 0 | DJ36: 0 | DK36: 0 | DL36: 0 | EH36: =SUM(CP36:EG36) -> 7 | EI36: =SUM(C36:DM36) -> 152 | EJ36: =SUM(J36:DM36) -> 95 | EK36: =SUM(DL36:EG36) -> 0 | EL36: =SUM(C36:C36) -> 12 | EM36: =SUM(D36:O36) -> 62 | EN36: =SUM(P36:AA36) -> 5 | EO36: =SUM(AB36:AM36) -> 17 | EP36: =SUM(AN36:AY36) -> 24 | EQ36: =SUM(AZ36:BW36) -> 15 | ER36: =SUM(BX36:CU36) -> 11 | ES36: =SUM(CV36:DS36) -> 6 | ET36: =SUM(DT36:EG36) -> 0 | EU36: =SUM(BP36:CK36) -> 13 | EV36: =SUM(CD36:CU36) -> 8 | EX36: =SUM(C36:CO36) -> 145 | EY36: =SUM(F36:DK36) -> 115
A37: Ciberinvestigaciones | B37: Delitos Electorales | C37: 14 | D37: 5 | E37: 7 | F37: 3 | G37: 6 | H37: 2 | I37: 14 | J37: 3 | K37: 4 | L37: 2 | M37: 5 | N37: 2 | O37: 0 | P37: 0 | Q37: 0 | R37: 0 | S37: 0 | T37: 0 | U37: 0 | V37: 0 | W37: 0 | X37: 0 | Y37: 0 | Z37: 0 | AA37: 0 | AB37: 0 | AC37: 0 | AD37: 0 | AE37: 0 | AF37: 3 | AG37: 8 | AH37: 6 | AI37: 1 | AJ37: 1 | AK37: 4 | AL37: 4 | AM37: 3 | AN37: 1 | AO37: 0 | AP37: 0 | AQ37: 0 | AR37: 0 | AS37: 1 | AT37: 0 | AU37: 0 | AV37: 1 | AW37: 1 | AX37: 0 | AY37: 1 | AZ37: 0 | BA37: 0 | BB37: 0 | BC37: 0 | BD37: 0 | BE37: 0 | BF37: 0 | BG37: 0 | BH37: 0 | BI37: 0 | BJ37: 0 | BK37: 0 | BL37: 1 | BM37: 0 | BN37: 0 | BO37: 0 | BP37: 1 | BQ37: 0 | BR37: 0 | BS37: 0 | BT37: 0 | BU37: 0 | BV37: 0 | BW37: 0 | BX37: 0 | BY37: 0 | BZ37: 0 | CA37: 0 | CB37: 0 | CC37: 0 | CD37: 2 | CE37: 0 | CF37: 0 | CG37: 0 | CH37: 1 | CI37: 0 | CJ37: 0 | CK37: 0 | CL37: 0 | CM37: 0 | CN37: 0 | CO37: 0 | CP37: 0 | CQ37: 0 | CR37: 0 | CS37: 0 | CT37: 0 | CU37: 0 | CV37: 0 | CW37: 0 | CX37: 0 | CY37: 0 | CZ37: 0 | DA37: 0 | DB37: 0 | DC37: 0 | DD37: 0 | DE37: 0 | DF37: 0 | DG37: 0 | DH37: 0 | DI37: 0 | DJ37: 0 | DK37: 0 | DL37: 0 | EH37: =SUM(CP37:EG37) -> 0 | EI37: =SUM(C37:DM37) -> 107 | EJ37: =SUM(J37:DM37) -> 56 | EK37: =SUM(DL37:EG37) -> 0 | EL37: =SUM(C37:C37) -> 14 | EM37: =SUM(D37:O37) -> 53 | EN37: =SUM(P37:AA37) -> 0 | EO37: =SUM(AB37:AM37) -> 30 | EP37: =SUM(AN37:AY37) -> 5 | EQ37: =SUM(AZ37:BW37) -> 2 | ER37: =SUM(BX37:CU37) -> 3 | ES37: =SUM(CV37:DS37) -> 0 | ET37: =SUM(DT37:EG37) -> 0 | EU37: =SUM(BP37:CK37) -> 4 | EV37: =SUM(CD37:CU37) -> 3 | EX37: =SUM(C37:CO37) -> 107 | EY37: =SUM(F37:DK37) -> 81
A38: Ciberinvestigaciones | B38: Violacion contra la intimidad sexual | C38: 6 | D38: 0 | E38: 0 | F38: 0 | G38: 2 | H38: 0 | I38: 2 | J38: 1 | K38: 3 | L38: 2 | M38: 5 | N38: 3 | O38: 3 | P38: 1 | Q38: 1 | R38: 1 | S38: 0 | T38: 0 | U38: 0 | V38: 0 | W38: 4 | X38: 2 | Y38: 2 | Z38: 3 | AA38: 0 | AB38: 6 | AC38: 0 | AD38: 3 | AE38: 1 | AF38: 4 | AG38: 9 | AH38: 0 | AI38: 18 | AJ38: 9 | AK38: 3 | AL38: 7 | AM38: 3 | AN38: 4 | AO38: 4 | AP38: 1 | AQ38: 1 | AR38: 4 | AS38: 6 | AT38: 3 | AU38: 0 | AV38: 2 | AW38: 4 | AX38: 0 | AY38: 6 | AZ38: 1 | BA38: 4 | BB38: 0 | BC38: 1 | BD38: 0 | BE38: 0 | BF38: 1 | BG38: 1 | BH38: 3 | BI38: 1 | BJ38: 3 | BK38: 2 | BL38: 1 | BM38: 3 | BN38: 1 | BO38: 0 | BP38: 7 | BQ38: 0 | BR38: 3 | BS38: 0 | BT38: 2 | BU38: 1 | BV38: 1 | BW38: 2 | BX38: 3 | BY38: 1 | BZ38: 2 | CA38: 2 | CB38: 7 | CC38: 3 | CD38: 1 | CE38: 3 | CF38: 0 | CG38: 0 | CH38: 0 | CI38: 0 | CJ38: 0 | CK38: 4 | CL38: 0 | CM38: 9 | CN38: 1 | CO38: 1 | CP38: 3 | CQ38: 3 | CR38: 1 | CS38: 2 | CT38: 0 | CU38: 0 | CV38: 0 | CW38: 4 | CX38: 0 | CY38: 1 | CZ38: 1 | DA38: 0 | DB38: 2 | DC38: 0 | DD38: 1 | DE38: 0 | DF38: 8 | DG38: 1 | DH38: 4 | DI38: 3 | DJ38: 0 | DK38: 0 | DL38: 1 | DM38: 2 | EH38: =SUM(CP38:EG38) -> 37 | EI38: =SUM(C38:DM38) -> 251 | EJ38: =SUM(J38:DM38) -> 241 | EK38: =SUM(DL38:EG38) -> 3 | EL38: =SUM(C38:C38) -> 6 | EM38: =SUM(D38:O38) -> 21 | EN38: =SUM(P38:AA38) -> 14 | EO38: =SUM(AB38:AM38) -> 63 | EP38: =SUM(AN38:AY38) -> 35 | EQ38: =SUM(AZ38:BW38) -> 38 | ER38: =SUM(BX38:CU38) -> 46 | ES38: =SUM(CV38:DS38) -> 28 | ET38: =SUM(DT38:EG38) -> 0 | EU38: =SUM(BP38:CK38) -> 42 | EV38: =SUM(CD38:CU38) -> 28 | EX38: =SUM(C38:CO38) -> 214 | EY38: =SUM(F38:DK38) -> 242
A39: Ciberinvestigaciones | B39: Otros Delitos | C39: 64 | D39: 61 | E39: 41 | F39: 46 | G39: 32 | H39: 21 | I39: 34 | J39: 37 | K39: 35 | L39: 50 | M39: 68 | N39: 40 | O39: 23 | P39: 24 | Q39: 34 | R39: 43 | S39: 16 | T39: 4 | U39: 18 | V39: 15 | W39: 37 | X39: 21 | Y39: 21 | Z39: 7 | AA39: 35 | AB39: 14 | AC39: 16 | AD39: 35 | AE39: 33 | AF39: 17 | AG39: 32 | AH39: 22 | AI39: 30 | AJ39: 11 | AK39: 16 | AL39: 33 | AM39: 40 | AN39: 69 | AO39: 38 | AP39: 29 | AQ39: 26 | AR39: 24 | AS39: 25 | AT39: 27 | AU39: 23 | AV39: 18 | AW39: 36 | AX39: 24 | AY39: 13 | AZ39: 10 | BA39: 10 | BB39: 10 | BC39: 9 | BD39: 6 | BE39: 14 | BF39: 11 | BG39: 9 | BH39: 10 | BI39: 15 | BJ39: 12 | BK39: 6 | BL39: 16 | BM39: 4 | BN39: 12 | BO39: 15 | BP39: 9 | BQ39: 10 | BR39: 5 | BS39: 7 | BT39: 11 | BU39: 11 | BV39: 3 | BW39: 8 | BX39: 9 | BY39: 7 | BZ39: 11 | CA39: 8 | CB39: 2 | CC39: 11 | CD39: 7 | CE39: 14 | CF39: 13 | CG39: 9 | CH39: 8 | CI39: 8 | CJ39: 7 | CK39: 18 | CL39: 4 | CM39: 12 | CN39: 7 | CO39: 14 | CP39: 5 | CQ39: 6 | CR39: 8 | CS39: 13 | CT39: 7 | CU39: 2 | CV39: 4 | CW39: 11 | CX39: 9 | CY39: 0 | CZ39: 10 | DA39: 3 | DB39: 7 | DC39: 8 | DD39: 8 | DE39: 6 | DF39: 13 | DG39: 6 | DH39: 3 | DI39: 2 | DJ39: 20 | DK39: 10 | DL39: 4 | DM39: 1 | DN39: 1 | DO39: 1 | DT39: 1 | DU39: 2 | DV39: 0 | DW39: 1 | DX39: 0 | DY39: 0 | DZ39: 1 | EA39: 2 | EB39: 0 | EC39: 0 | ED39: 0 | EE39: 1 | EF39: 1 | EG39: 1 | EH39: =SUM(CP39:EG39) -> 178 | EI39: =SUM(C39:DM39) -> 2046 | EJ39: =SUM(J39:DM39) -> 1747 | EK39: =SUM(DL39:EG39) -> 17 | EL39: =SUM(C39:C39) -> 64 | EM39: =SUM(D39:O39) -> 488 | EN39: =SUM(P39:AA39) -> 275 | EO39: =SUM(AB39:AM39) -> 299 | EP39: =SUM(AN39:AY39) -> 352 | EQ39: =SUM(AZ39:BW39) -> 233 | ER39: =SUM(BX39:CU39) -> 210 | ES39: =SUM(CV39:DS39) -> 127 | ET39: =SUM(DT39:EG39) -> 10 | EU39: =SUM(BP39:CK39) -> 196 | EV39: =SUM(CD39:CU39) -> 162 | EX39: =SUM(C39:CO39) -> 1880 | EY39: =SUM(F39:DK39) -> 1875
A40: Denuncias - Todas | B40: Denuncias - Todas | C40: =SUM(C41:C52) -> 5 | D40: =SUM(D41:D52) -> 3 | E40: =SUM(E41:E52) -> 2 | F40: =SUM(F41:F52) -> 5 | G40: =SUM(G41:G52) -> 3 | H40: =SUM(H41:H52) -> 6 | I40: =SUM(I41:I52) -> 1 | J40: =SUM(J41:J52) -> 4 | ... AS40: =SUM(AS41:AS52) -> 8 | AT40: 8 | AU40: 7 | AV40: 8 | AW40: 7 | AX40: 9 | AY40: 8 | AZ40: 1 | BA40: 7 | BB40: 4 | BC40: 3 | BD40: 4 | BE40: 4 | BF40: 5 | BG40: 4 | BH40: 4 | BI40: 4 | BJ40: 4 | BK40: 5 | BL40: 2 | BM40: 6 | BN40: 2 | BO40: 6 | BP40: 4 | BQ40: 4 | BR40: 4 | BS40: 5 | BT40: 2 | BU40: 7 | BV40: 4 | BW40: 8 | BX40: 3 | BY40: 5 | BZ40: 0 | CA40: 8 | CB40: 2 | CC40: 2 | CD40: 5 | CE40: 3 | CF40: 2 | CG40: 2 | CH40: 5 | CI40: 1 | CJ40: 4 | CK40: 5 | CL40: 4 | CM40: 7 | CN40: 5 | CO40: 8 | CP40: 5 | CQ40: 5 | CR40: 6 | CS40: 6 | CT40: 5 | CU40: 11 | CV40: 1 | CW40: 7 | CX40: 7 | CY40: 6 | CZ40: 4 | DA40: 1 | DB40: 3 | DC40: 2 | DD40: 3 | DE40: 1 | DF40: 7 | DG40: 11 | DH40: 9 | DI40: 5 | DJ40: 4 | DK40: 0 | DL40: 2 | DM40: 0 | DN40: 1 | DO40: 0 | DP40: 2 | DQ40: 2 | DR40: 3 | DS40: 4 | EH40: =SUM(CP40:EG40) -> 123 | EI40: =SUM(C40:DM40) -> 637 | EJ40: =SUM(J40:DM40) -> 612 | EK40: =SUM(DL40:EG40) -> 14 | EL40: =SUM(C40:C40) -> 5 | EM40: =SUM(D40:O40) -> 60 | EN40: =SUM(P40:AA40) -> 80 | EO40: =SUM(AB40:AM40) -> 91 | EP40: =SUM(AN40:AY40) -> 116 | EQ40: =SUM(AZ40:BW40) -> 103 | ER40: =SUM(BX40:CU40) -> 109 | ES40: =SUM(CV40:DS40) -> 85 | ET40: =SUM(DT40:EG40) -> 0 | EU40: =SUM(BP40:CK40) -> 85 | EV40: =SUM(CD40:CU40) -> 89 | EX40: =SUM(C40:CO40) -> 526 | EY40: =SUM(F40:DK40) -> 625
A41: Denuncias - Todas | B41: Delitos contra el ambiente | C41: 0 | D41: 0 | E41: 0 | F41: 0 | G41: 0 | H41: 0 | I41: 0 | J41: 0 | K41: 0 | L41: 0 | M41: 0 | N41: 0 | O41: 0 | P41: 0 | Q41: 0 | R41: 0 | S41: 0 | T41: 0 | U41: 0 | V41: 0 | W41: 0 | X41: 0 | Y41: 0 | Z41: 0 | AA41: 0 | AB41: 0 | AC41: 0 | AD41: 2 | AE41: 0 | AF41: 0 | AG41: 4 | AH41: 0 | AI41: 0 | AJ41: 0 | AK41: 2 | AL41: 0 | AM41: 0 | AN41: 0 | AO41: 4 | AP41: 2 | AQ41: 2 | AR41: 2 | AS41: 0 | AT41: 0 | AU41: 1 | AV41: 0 | AW41: 0 | AX41: 3 | AY41: 1 | AZ41: 0 | BA41: 0 | BB41: 0 | BC41: 0 | BD41: 0 | BE41: 0 | BF41: 1 | BG41: 1 | BH41: 0 | BI41: 1 | BJ41: 0 | BK41: 0 | BL41: 0 | BM41: 0 | BN41: 0 | BO41: 0 | BP41: 0 | BQ41: 0 | BR41: 0 | BS41: 0 | BT41: 0 | BU41: 0 | BV41: 0 | BW41: 0 | BX41: 0 | BY41: 0 | BZ41: 0 | CA41: 0 | CB41: 0 | CC41: 0 | CD41: 2 | CE41: 0 | CF41: 0 | CG41: 0 | CH41: 0 | CI41: 0 | CJ41: 0 | CK41: 0 | CL41: 0 | CM41: 0 | CN41: 0 | CO41: 0 | CP41: 0 | CQ41: 0 | CR41: 0 | CS41: 0 | CT41: 0 | CU41: 0 | CV41: 0 | CW41: 0 | CX41: 0 | CY41: 2 | CZ41: 0 | DA41: 0 | DB41: 1 | DC41: 0 | DD41: 0 | DE41: 0 | DF41: 0 | DG41: 0 | DH41: 0 | DI41: 0 | DJ41: 0 | DK41: 0 | DL41: 0 | DM41: 0 | DN41: 0 | DO41: 0 | DP41: 0 | EH41: =SUM(CP41:EG41) -> 3 | EI41: =SUM(C41:DM41) -> 31 | EJ41: =SUM(J41:DM41) -> 31 | EK41: =SUM(DL41:EG41) -> 0 | EL41: =SUM(C41:C41) -> 0 | EM41: =SUM(D41:O41) -> 0 | EN41: =SUM(P41:AA41) -> 0 | EO41: =SUM(AB41:AM41) -> 8 | EP41: =SUM(AN41:AY41) -> 15 | EQ41: =SUM(AZ41:BW41) -> 3 | ER41: =SUM(BX41:CU41) -> 2 | ES41: =SUM(CV41:DS41) -> 3 | ET41: =SUM(DT41:EG41) -> 0 | EU41: =SUM(BP41:CK41) -> 2 | EV41: =SUM(CD41:CU41) -> 2 | EX41: =SUM(C41:CO41) -> 28 | EY41: =SUM(F41:DK41) -> 31
A42: Denuncias - Todas | B42: Falsificación de papel moneda | C42: 0 | D42: 0 | E42: 0 | F42: 0 | G42: 0 | H42: 0 | I42: 0 | J42: 0 | K42: 0 | L42: 0 | M42: 0 | N42: 0 | O42: 0 | P42: 0 | Q42: 0 | R42: 0 | S42: 0 | T42: 0 | U42: 0 | V42: 0 | W42: 0 | X42: 0 | Y42: 0 | Z42: 0 | AA42: 0 | AB42: 0 | AC42: 0 | AD42: 0 | AE42: 0 | AF42: 0 | AG42: 0 | AH42: 4 | AI42: 0 | AJ42: 0 | AK42: 0 | AL42: 0 | AM42: 0 | AN42: 0 | AO42: 1 | AP42: 1 | AQ42: 0 | AR42: 2 | AS42: 0 | AT42: 2 | AU42: 0 | AV42: 2 | AW42: 0 | AX42: 0 | AY42: 0 | AZ42: 0 | BA42: 0 | BB42: 0 | BC42: 0 | BD42: 0 | BE42: 0 | BF42: 0 | BG42: 0 | BH42: 0 | BI42: 0 | BJ42: 0 | BK42: 0 | BL42: 0 | BM42: 0 | BN42: 0 | BO42: 0 | BP42: 0 | BQ42: 0 | BR42: 0 | BS42: 0 | BT42: 0 | BU42: 0 | BV42: 0 | BW42: 0 | BX42: 0 | BY42: 0 | BZ42: 0 | CA42: 0 | CB42: 0 | CC42: 0 | CD42: 0 | CE42: 0 | CF42: 0 | CG42: 0 | CH42: 0 | CI42: 0 | CJ42: 0 | CK42: 0 | CL42: 0 | CM42: 0 | CN42: 0 | CO42: 0 | CP42: 0 | CQ42: 0 | CR42: 0 | CS42: 0 | CT42: 0 | CU42: 0 | CV42: 0 | CW42: 0 | CX42: 0 | CY42: 0 | CZ42: 0 | DA42: 0 | DB42: 0 | DC42: 0 | DD42: 0 | DE42: 0 | DF42: 0 | DG42: 0 | DH42: 0 | DI42: 0 | DJ42: 0 | DK42: 0 | DL42: 0 | DM42: 0 | DN42: 0 | DO42: 0 | DP42: 0 | EH42: =SUM(CP42:EG42) -> 0 | EI42: =SUM(C42:DM42) -> 12 | EJ42: =SUM(J42:DM42) -> 12 | EK42: =SUM(DL42:EG42) -> 0 | EL42: =SUM(C42:C42) -> 0 | EM42: =SUM(D42:O42) -> 0 | EN42: =SUM(P42:AA42) -> 0 | EO42: =SUM(AB42:AM42) -> 4 | EP42: =SUM(AN42:AY42) -> 8 | EQ42: =SUM(AZ42:BW42) -> 0 | ER42: =SUM(BX42:CU42) -> 0 | ES42: =SUM(CV42:DS42) -> 0 | ET42: =SUM(DT42:EG42) -> 0 | EU42: =SUM(BP42:CK42) -> 0 | EV42: =SUM(CD42:CU42) -> 0 | EX42: =SUM(C42:CO42) -> 12 | EY42: =SUM(F42:DK42) -> 12
A43: Denuncias - Todas | B43: Violencia de Género | C43: 0 | D43: 0 | E43: 0 | F43: 0 | G43: 0 | H43: 0 | I43: 0 | J43: 0 | K43: 0 | L43: 0 | M43: 0 | N43: 0 | O43: 0 | P43: 0 | Q43: 0 | R43: 0 | S43: 0 | T43: 0 | U43: 0 | V43: 0 | W43: 0 | X43: 0 | Y43: 0 | Z43: 0 | AA43: 0 | AB43: 0 | AC43: 0 | AD43: 0 | AE43: 0 | AF43: 0 | AG43: 0 | AH43: 0 | AI43: 0 | AJ43: 0 | AK43: 0 | AL43: 0 | AM43: 0 | AN43: 0 | AO43: 3 | AP43: 3 | AQ43: 2 | AR43: 3 | AS43: 0 | AT43: 0 | AU43: 0 | AV43: 0 | AW43: 0 | AX43: 0 | AY43: 0 | AZ43: 0 | BA43: 0 | BB43: 0 | BC43: 0 | BD43: 0 | BE43: 0 | BF43: 0 | BG43: 0 | BH43: 0 | BI43: 0 | BJ43: 0 | BK43: 0 | BL43: 0 | BM43: 0 | BN43: 0 | BO43: 1 | BP43: 0 | BQ43: 0 | BR43: 0 | BS43: 1 | BT43: 0 | BU43: 0 | BV43: 0 | BW43: 0 | BX43: 0 | BY43: 0 | BZ43: 0 | CA43: 0 | CB43: 0 | CC43: 0 | CD43: 0 | CE43: 0 | CF43: 0 | CG43: 0 | CH43: 0 | CI43: 0 | CJ43: 0 | CK43: 0 | CL43: 0 | CM43: 0 | CN43: 0 | CO43: 0 | CP43: 0 | CQ43: 0 | CR43: 0 | CS43: 0 | CT43: 0 | CU43: 0 | CV43: 0 | CW43: 0 | CX43: 0 | CY43: 0 | CZ43: 0 | DA43: 0 | DB43: 0 | DC43: 0 | DD43: 0 | DE43: 0 | DF43: 0 | DG43: 0 | DH43: 0 | DI43: 0 | DJ43: 0 | DK43: 0 | DL43: 0 | DM43: 0 | DN43: 0 | DO43: 0 | DP43: 0 | EH43: =SUM(CP43:EG43) -> 0 | EI43: =SUM(C43:DM43) -> 13 | EJ43: =SUM(J43:DM43) -> 13 | EK43: =SUM(DL43:EG43) -> 0 | EL43: =SUM(C43:C43) -> 0 | EM43: =SUM(D43:O43) -> 0 | EN43: =SUM(P43:AA43) -> 0 | EO43: =SUM(AB43:AM43) -> 0 | EP43: =SUM(AN43:AY43) -> 11 | EQ43: =SUM(AZ43:BW43) -> 2 | ER43: =SUM(BX43:CU43) -> 0 | ES43: =SUM(CV43:DS43) -> 0 | ET43: =SUM(DT43:EG43) -> 0 | EU43: =SUM(BP43:CK43) -> 1 | EV43: =SUM(CD43:CU43) -> 0 | EX43: =SUM(C43:CO43) -> 13 | EY43: =SUM(F43:DK43) -> 13
A44: Denuncias - Todas | B44: Tráfico de personas (migrantes) | C44: 0 | D44: 0 | E44: 0 | F44: 0 | G44: 0 | H44: 0 | I44: 0 | J44: 0 | K44: 0 | L44: 0 | M44: 0 | N44: 0 | O44: 0 | P44: 0 | Q44: 0 | R44: 0 | S44: 0 | T44: 0 | U44: 0 | V44: 0 | W44: 0 | X44: 0 | Y44: 0 | Z44: 0 | AA44: 0 | AB44: 0 | AC44: 0 | AD44: 0 | AE44: 0 | AF44: 0 | AG44: 0 | AH44: 0 | AI44: 0 | AJ44: 0 | AK44: 0 | AL44: 0 | AM44: 0 | AN44: 0 | AO44: 1 | AP44: 0 | AQ44: 0 | AR44: 1 | AS44: 0 | AT44: 0 | AU44: 0 | AV44: 0 | AW44: 0 | AX44: 0 | AY44: 0 | AZ44: 1 | BA44: 0 | BB44: 0 | BC44: 0 | BD44: 1 | BE44: 0 | BF44: 0 | BG44: 0 | BH44: 0 | BI44: 0 | BJ44: 0 | BK44: 0 | BL44: 0 | BM44: 0 | BN44: 0 | BO44: 0 | BP44: 0 | BQ44: 0 | BR44: 0 | BS44: 0 | BT44: 0 | BU44: 0 | BV44: 0 | BW44: 0 | BX44: 0 | BY44: 0 | BZ44: 0 | CA44: 0 | CB44: 0 | CC44: 0 | CD44: 1 | CE44: 1 | CF44: 0 | CG44: 0 | CH44: 0 | CI44: 0 | CJ44: 0 | CK44: 0 | CL44: 0 | CM44: 0 | CN44: 0 | CO44: 0 | CP44: 0 | CQ44: 0 | CR44: 0 | CS44: 0 | CT44: 0 | CU44: 0 | CV44: 0 | CW44: 0 | CX44: 0 | CY44: 0 | CZ44: 0 | DA44: 0 | DB44: 0 | DC44: 0 | DD44: 0 | DE44: 0 | DF44: 0 | DG44: 0 | DH44: 0 | DI44: 0 | DJ44: 0 | DK44: 0 | DL44: 0 | DM44: 0 | DN44: 0 | DO44: 0 | DP44: 0 | EH44: =SUM(CP44:EG44) -> 0 | EI44: =SUM(C44:DM44) -> 6 | EJ44: =SUM(J44:DM44) -> 6 | EK44: =SUM(DL44:EG44) -> 0 | EL44: =SUM(C44:C44) -> 0 | EM44: =SUM(D44:O44) -> 0 | EN44: =SUM(P44:AA44) -> 0 | EO44: =SUM(AB44:AM44) -> 0 | EP44: =SUM(AN44:AY44) -> 2 | EQ44: =SUM(AZ44:BW44) -> 2 | ER44: =SUM(BX44:CU44) -> 2 | ES44: =SUM(CV44:DS44) -> 0 | ET44: =SUM(DT44:EG44) -> 0 | EU44: =SUM(BP44:CK44) -> 2 | EV44: =SUM(CD44:CU44) -> 2 | EX44: =SUM(C44:CO44) -> 6 | EY44: =SUM(F44:DK44) -> 6
A45: Denuncias - Todas | B45: Trata de Personas | C45: 1 | D45: 0 | E45: 0 | F45: 0 | G45: 0 | H45: 0 | I45: 0 | J45: 3 | K45: 3 | L45: 0 | M45: 3 | N45: 1 | O45: 0 | P45: 0 | Q45: 0 | R45: 0 | S45: 0 | T45: 0 | U45: 2 | V45: 0 | W45: 1 | X45: 0 | Y45: 0 | Z45: 0 | AA45: 0 | AB45: 1 | AC45: 0 | AD45: 0 | AE45: 0 | AF45: 0 | AG45: 0 | AH45: 0 | AI45: 0 | AJ45: 0 | AK45: 0 | AL45: 0 | AM45: 0 | AN45: 0 | AO45: 0 | AP45: 0 | AQ45: 0 | AR45: 0 | AS45: 0 | AT45: 0 | AU45: 0 | AV45: 0 | AW45: 0 | AX45: 0 | AY45: 0 | AZ45: 0 | BA45: 0 | BB45: 0 | BC45: 0 | BD45: 0 | BE45: 0 | BF45: 0 | BG45: 0 | BH45: 0 | BI45: 0 | BJ45: 0 | BK45: 0 | BL45: 0 | BM45: 0 | BN45: 0 | BO45: 0 | BP45: 0 | BQ45: 0 | BR45: 0 | BS45: 0 | BT45: 0 | BU45: 0 | BV45: 0 | BW45: 0 | BX45: 0 | BY45: 0 | BZ45: 0 | CA45: 0 | CB45: 0 | CC45: 0 | CD45: 0 | CE45: 0 | CF45: 0 | CG45: 0 | CH45: 0 | CI45: 0 | CJ45: 0 | CK45: 0 | CL45: 0 | CM45: 0 | CN45: 0 | CO45: 0 | CP45: 0 | CQ45: 0 | CR45: 0 | CS45: 0 | CT45: 0 | CU45: 0 | CV45: 0 | CW45: 0 | CX45: 0 | CY45: 0 | CZ45: 0 | DA45: 0 | DB45: 0 | DC45: 0 | DD45: 0 | DE45: 0 | DF45: 0 | DG45: 0 | DH45: 0 | DI45: 0 | DJ45: 0 | DK45: 0 | DL45: 0 | DM45: 0 | DN45: 0 | DO45: 0 | DP45: 0 | EH45: =SUM(CP45:EG45) -> 0 | EI45: =SUM(C45:DM45) -> 15 | EJ45: =SUM(J45:DM45) -> 14 | EK45: =SUM(DL45:EG45) -> 0 | EL45: =SUM(C45:C45) -> 1 | EM45: =SUM(D45:O45) -> 10 | EN45: =SUM(P45:AA45) -> 3 | EO45: =SUM(AB45:AM45) -> 1 | EP45: =SUM(AN45:AY45) -> 0 | EQ45: =SUM(AZ45:BW45) -> 0 | ER45: =SUM(BX45:CU45) -> 0 | ES45: =SUM(CV45:DS45) -> 0 | ET45: =SUM(DT45:EG45) -> 0 | EU45: =SUM(BP45:CK45) -> 0 | EV45: =SUM(CD45:CU45) -> 0 | EX45: =SUM(C45:CO45) -> 15 | EY45: =SUM(F45:DK45) -> 14
...

Sheet observaciones alertas y boletin
A3: Alertas y Boletínes | B3: Alertas y Boletínes | C3: 32 | D3: 51 | E3: 47 | F3: 37 | G3: 48 | H3: 46 | I3: 40 | J3: 49 | K3: 18 | L3: 12 | M3: 24 | N3: 39 | O3: 20 | P3: 31 | Q3: 46 | R3: 78 | S3: 37 | T3: 41 | U3: 31 | V3: 18 | W3: 24 | X3: 9 | Y3: 26 | Z3: =SUM(C3:Y3) -> 804 | AA3: =SUM(#REF!) -> #REF! | AB3: =SUM(#REF!) -> #REF! | AC3: =SUM(#REF!) -> #REF! | AD3: =SUM(#REF!) -> #REF! | AE3: =SUM(#REF!) -> #REF! | AF3: =SUM(#REF!) -> #REF! | AG3: =SUM(C3:Y3) -> 804
A4: Alertas | B4: Gubernamental | C4: 14 | D4: 19 | E4: 15 | F4: 11 | G4: 25 | H4: 15 | I4: 19 | J4: 13 | K4: 3 | L4: 3 | M4: 0 | N4: 14 | O4: 2 | P4: 5 | Q4: 9 | R4: 15 | S4: 14 | T4: 9 | U4: 3 | V4: 1 | W4: 2 | X4: 2 | Y4: 1 | Z4: =SUM(C4:Y4) -> 214 | AA4: =SUM(#REF!) -> #REF! | AB4: =SUM(#REF!) -> #REF! | AC4: =SUM(#REF!) -> #REF! | AD4: =SUM(#REF!) -> #REF! | AE4: =SUM(#REF!) -> #REF! | AF4: =SUM(#REF!) -> #REF! | AG4: =SUM(C4:Y4) -> 214 | AH4: 214
A5: Boletines | B5: Gubernamental | C5: 18 | D5: 32 | E5: 32 | F5: 26 | G5: 23 | H5: 31 | I5: 21 | J5: 36 | K5: 15 | L5: 9 | M5: 24 | N5: 25 | O5: 18 | P5: 26 | Q5: 37 | R5: 63 | S5: 23 | T5: 32 | U5: 28 | V5: 17 | W5: 22 | X5: 7 | Y5: 25 | Z5: =SUM(C5:Y5) -> 590 | AA5: =SUM(#REF!) -> #REF! | AB5: =SUM(#REF!) -> #REF! | AC5: =SUM(#REF!) -> #REF! | AD5: =SUM(#REF!) -> #REF! | AE5: =SUM(#REF!) -> #REF! | AF5: =SUM(#REF!) -> #REF! | AG5: =SUM(C5:Y5) -> 590 | AH5: 590

Sheet Hoja4
C3: 23 | D3: 18 | E3: 6 | F3: 22 | G3: 22 | H3: 16 | I3: 8 | J3: 11 | K3: 18 | L3: 4 | M3: 5 | N3: 14 | O3: 6 | P3: 3 | Q3: 2 | R3: 6 | S3: 5 | T3: 5 | U3: 4 | V3: 6 | W3: 4 | X3: 5 | Y3: 17 | Z3: 5 | AA3: 12 | AB3: 5 | AC3: 17 | AD3: 12 | AE3: 40 | AF3: 5 | AG3: 5 | AH3: 1 | AI3: 5 | AJ3: 5 | AK3: 17 | AL3: 11 | AM3: 25 | AN3: 10 | AO3: 12 | AP3: 62 | AQ3: 16 | AR3: 11 | AS3: =SUM(C3:AR3) -> 506
C4: 23 | D4: 18 | E4: 6 | F4: 22 | G4: 22 | H4: 16 | I4: 8 | J4: 11 | K4: 18 | L4: 4 | M4: 5 | N4: 14 | O4: 6 | P4: 3 | Q4: 2 | R4: 6 | S4: 5 | T4: 5 | U4: 4 | V4: 6 | W4: 4 | X4: 5 | Y4: 17 | Z4: 5 | AA4: 12 | AB4: 5 | AC4: 17 | AD4: 12 | AE4: 40 | AF4: 5 | AG4: 5 | AH4: 1 | AI4: 5 | AJ4: 5 | AK4: 17 | AL4: 11 | AM4: 25 | AN4: 10 | AO4: 12 | AP4: 16 | AQ4: 16 | AR4: 11 | AS4: =SUM(C4:AR4) -> 460

Sheet Hoja3
H5: Amenazas | I5: 3 | J5: 0 | K5: =SUM(I5:J5) -> 3
H6: Desaparición Forzada | I6: 0 | J6: 0 | K6: =SUM(I6:J6) -> 0
H7: Fraude | I7: 0 | J7: 0 | K7: =SUM(I7:J7) -> 0
H8: Personas Desaparecidas | I8: 3 | J8: 1 | K8: =SUM(I8:J8) -> 4
H9: Pornografía Infantil | I9: 11 | J9: 11 | K9: =SUM(I9:J9) -> 22
H10: Secuestro | I10: 1 | J10: 1 | K10: =SUM(I10:J10) -> 2
H11: Trata de Personas | I11: 2 | J11: 1 | K11: =SUM(I11:J11) -> 3
H12: Menor desaparecido | I12: 0 | J12: 0 | K12: =SUM(I12:J12) -> 0
H13: Otros Delitos | I13: 11 | J13: 16 | K13: =SUM(I13:J13) -> 27
G15: 27 | H15: Otros Delitos
G16: 22 | H16: Pornografía Infantil
G17: 4 | H17: Personas Desaparecidas
G18: 3 | H18: Amenazas
G19: 3 | H19: Trata de Personas
G20: 2 | H20: Secuestro
G21: =SUM(G15:G20) -> 61

Sheet Dic18-2026 -Nvo For_ CERT-PREV
EJ1: GUARDIA NACIONAL
EJ2: UNIDAD DE ÓRGANOS ESPECIALIZADOS POR COMPETENCIA
EJ3: DIRECCIÓN GENERAL CIENTÍFICA
A5: INFORME DE ACCIONES Y RESULTADOS EN EL MARCO DE LA ESTRATEGIA NACIONAL DE SEGURIDAD PÚBLICA (ENSP)
A8: VIII. SEGURIDAD PÚBLICA, SEGURIDAD NACIONAL Y PAZ
A10: CIBERSEGURIDAD
